Workbook

Sheet Unit-upper left
A2: Wastewater treatement
A4: Cost | B4: {=[1]!Annualized_Cost} -> 854004.86 | C4: $/year
A5: Usage of IER | B5: =[1]OUTPUT!$C$426 -> 26.010714 | C5: ton/year | D5: all throwaway without any regeneration
A6: Unit absorption ability | B6: =[2]IER!$A$37 -> 1.05 | C6: =[2]IER!$B$1 -> g/gPFAS convert via GAC weight
A8: Unit price | B8: =B4/B5/B6/1000 -> 31.269344 | C8: $/kg
A11: Solvent
A13: Cost | B13: {=[3]!Annualized_Cost} -> 3.4636212e+09 | C13: $/year
A14: destruction | B14: =[3]OUTPUT!$C$425*3.785 -> 2971225000 | C14: kgPFAS/year
A15: unit price | B15: =B13/B14 -> 1.1657216 | C15: $/kg
A19: gas | B19: =B15 -> 1.1657216 | C19: $/kg
A23: solid | B23: =B15 -> 1.1657216 | C23: $/kg

Sheet upper middle
A1: 2030 | B1: Figure b | J1: Figurec | R1: Figure b
B2: agg | C2: dev | D2: mon | E2: dev | F2: con | G2: dev | S2: agg | T2: dev | U2: mon | V2: dev | W2: con | X2: dev
A3: wastewater | B3: =SUM(aggressive!B94:'aggressive'!G94)-SUM(aggressive!B90:'aggressive'!G90) -> 335.41916 | C3: =SUM(aggressive!H94:'aggressive'!H94)-SUM(aggressive!H90:'aggressive'!H90) -> 36.377279 | D3: =SUM(moderate!B94:'moderate'!G94)-SUM(moderate!B90:'moderate'!G90) -> 191.9862 | E3: =SUM(moderate!H94:'moderate'!H94)-SUM(moderate!H90:'moderate'!H90) -> 21.816045 | F3: =SUM(conservative!B94:'conservative'!G94)-SUM(conservative!B90:'conservative'!G90) -> 83.551085 | G3: =SUM(conservative!H94:'conservative'!H94)-SUM(conservative!H90:'conservative'!H90) -> 9.0640485 | J3: =aggressive!B2 -> photoacid generators | K3: =aggressive!C2 -> surfactant | L3: =aggressive!D2 -> Top antireflective coatings | M3: =aggressive!E2 -> polymer | N3: =aggressive!F2 -> immersion topcoat | O3: =aggressive!G2 -> PBO/PI | P3: =aggressive!H2 -> Dev_total | R3: wastewater | S3: 335.41916 | T3: 36.377279 | U3: 191.9862 | V3: 21.816045 | W3: 83.551085 | X3: 9.0640485
A4: solvent | B4: =SUM(aggressive!Z94:'aggressive'!AE94)-SUM(aggressive!Z90:'aggressive'!AE90) -> 14.02761 | C4: =SUM(aggressive!AF94:'aggressive'!AF94)-SUM(aggressive!AF90:'aggressive'!AF90) -> 1.5213525 | D4: =SUM(moderate!Z94:'moderate'!AE94)-SUM(moderate!Z90:'moderate'!AE90) -> 8.0291448 | E4: =SUM(moderate!AF94:'moderate'!AF94)-SUM(moderate!AF90:'moderate'!AF90) -> 0.91225869 | F4: =SUM(conservative!Z94:'conservative'!AE94)-SUM(conservative!Z90:'conservative'!AE90) -> 3.494985 | G4: =SUM(conservative!AF94:'conservative'!AF94)-SUM(conservative!AF90:'conservative'!AF90) -> 0.37907855 | I4: agg | J4: =aggressive!B94+aggressive!J94+aggressive!R94+aggressive!Z94-(aggressive!B90+aggressive!J90+aggressive!R90+aggressive!Z90) -> 11.863007 | K4: =aggressive!C94+aggressive!K94+aggressive!S94+aggressive!AA94-(aggressive!C90+aggressive!K90+aggressive!S90+aggressive!AA90) -> 4.1937185 | L4: =aggressive!D94+aggressive!L94+aggressive!T94+aggressive!AB94-(aggressive!D90+aggressive!L90+aggressive!T90+aggressive!AB90) -> 218.30279 | M4: =aggressive!E94+aggressive!M94+aggressive!U94+aggressive!AC94-(aggressive!E90+aggressive!M90+aggressive!U90+aggressive!AC90) -> 0.71800332 | N4: =aggressive!F94+aggressive!N94+aggressive!V94+aggressive!AD94-(aggressive!F90+aggressive!N90+aggressive!V90+aggressive!AD90) -> 107.77799 | O4: =aggressive!G94+aggressive!O94+aggressive!W94+aggressive!AE94-(aggressive!G90+aggressive!O90+aggressive!W90+aggressive!AE90) -> 6.8355555 | P4: =aggressive!H94+aggressive!P94+aggressive!X94+aggressive!AF94-(aggressive!H90+aggressive!P90+aggressive!X90+aggressive!AF90) -> 37.925126 | R4: solvent | S4: 14.024109 | T4: 1.5209728 | U4: 8.0271411 | V4: 0.91203103 | W4: 3.4941128 | X4: 0.37898395 | Z4: 151.83803 | AA4: =Z4/SUM($Z$4:$Z$6) -> 0.98253847
A5: gas | B5: =SUM(aggressive!R94:'aggressive'!W94)-SUM(aggressive!R90:'aggressive'!W90) -> 0.10665495 | C5: =SUM(aggressive!X94:'aggressive'!X94)-SUM(aggressive!X90:'aggressive'!X90) -> 0.011566956 | D5: =SUM(moderate!R94:'moderate'!W94)-SUM(moderate!R90:'moderate'!W90) -> 0.061046288 | E5: =SUM(moderate!X94:'moderate'!X94)-SUM(moderate!X90:'moderate'!X90) -> 0.0069379256 | F5: =SUM(conservative!R94:'conservative'!W94)-SUM(conservative!R90:'conservative'!W90) -> 0.026560472 | G5: =SUM(conservative!X94:'conservative'!X94)-SUM(conservative!X90:'conservative'!X90) -> 0.0028820586 | I5: mon | J5: =moderate!B94+moderate!J94+moderate!R94+moderate!Z94-(moderate!B90+moderate!J90+moderate!R90+moderate!Z90) -> 6.7900506 | K5: =moderate!C94+moderate!K94+moderate!S94+moderate!AA94-(moderate!C90+moderate!K90+moderate!S90+moderate!AA90) -> 2.4003662 | L5: =moderate!D94+moderate!L94+moderate!T94+moderate!AB94-(moderate!D90+moderate!L90+moderate!T90+moderate!AB90) -> 124.95212 | M5: =moderate!E94+moderate!M94+moderate!U94+moderate!AC94-(moderate!E90+moderate!M90+moderate!U90+moderate!AC90) -> 0.41096486 | N5: =moderate!F94+moderate!N94+moderate!V94+moderate!AD94-(moderate!F90+moderate!N90+moderate!V90+moderate!AD90) -> 61.689016 | O5: =moderate!G94+moderate!O94+moderate!W94+moderate!AE94-(moderate!G90+moderate!O90+moderate!W90+moderate!AE90) -> 3.9126512 | P5: =moderate!H94+moderate!P94+moderate!X94+moderate!AF94-(moderate!H90+moderate!P90+moderate!X90+moderate!AF90) -> 22.744193 | R5: gas | S5: 0.10662834 | T5: 0.011564069 | U5: 0.061031054 | V5: 0.0069361942 | W5: 0.026553844 | X5: 0.0028813394 | Z5: 1.215461 | AA5: =Z5/SUM($Z$4:$Z$6) -> 0.007865205
A6: solid | B6: =SUM(aggressive!J94:'aggressive'!O94)-SUM(aggressive!J90:'aggressive'!O90) -> 0.1376346 | C6: =SUM(aggressive!P94:'aggressive'!P94)-SUM(aggressive!P90:'aggressive'!P90) -> 0.014927074 | D6: =SUM(moderate!J94:'moderate'!O94)-SUM(moderate!J90:'moderate'!O90) -> 0.078779648 | E6: =SUM(moderate!P94:'moderate'!P94)-SUM(moderate!P90:'moderate'!P90) -> 0.0089505537 | F6: =SUM(conservative!J94:'conservative'!O94)-SUM(conservative!J90:'conservative'!O90) -> 0.034293446 | G6: =SUM(conservative!P94:'conservative'!P94)-SUM(conservative!P90:'conservative'!P90) -> 0.003719424 | I6: con | J6: =conservative!B94+conservative!J94+conservative!R94+conservative!Z94-(conservative!B90+conservative!J90+conservative!R90+conservative!Z90) -> 2.9542656 | K6: =conservative!C94+conservative!K94+conservative!S94+conservative!AA94-(conservative!C90+conservative!K90+conservative!S90+conservative!AA90) -> 1.0443692 | L6: =conservative!D94+conservative!L94+conservative!T94+conservative!AB94-(conservative!D90+conservative!L90+conservative!T90+conservative!AB90) -> 54.385788 | M6: =conservative!E94+conservative!M94+conservative!U94+conservative!AC94-(conservative!E90+conservative!M90+conservative!U90+conservative!AC90) -> 0.17880564 | N6: =conservative!F94+conservative!N94+conservative!V94+conservative!AD94-(conservative!F90+conservative!N90+conservative!V90+conservative!AD90) -> 26.839328 | O6: =conservative!G94+conservative!O94+conservative!W94+conservative!AE94-(conservative!G90+conservative!O90+conservative!W90+conservative!AE90) -> 1.7043668 | P6: =conservative!H94+conservative!P94+conservative!X94+conservative!AF94-(conservative!H90+conservative!P90+conservative!X90+conservative!AF90) -> 9.4497286 | R6: solid | S6: 0.13760026 | T6: 0.014923348 | U6: 0.078759988 | V6: 0.00894832 | W6: 0.034284888 | X6: 0.0037184958 | Z6: 1.4829817 | AA6: =Z6/SUM($Z$4:$Z$6) -> 0.0095963216
S7: =SUM(S4:S6) -> 14.268338 | T7: =SUM(T4:T6) -> 1.5474602 | U7: =SUM(U4:U6) -> 8.1669321 | V7: =SUM(V4:V6) -> 0.92791555 | W7: =SUM(W4:W6) -> 3.5549516 | X7: =SUM(X4:X6) -> 0.38558379
R9: wastewater | S9: 335.41916 | T9: 36.377279 | U9: 191.9862 | V9: 21.816045 | W9: 83.551085 | X9: 9.0640485
R10: Others | S10: 14.268338 | T10: 1.5474602 | U10: 8.1669321 | V10: 0.92791555 | W10: 3.5549516 | X10: 0.38558379
A13: Figure d
B15: aggressive | K15: moderate | U15: conservative
B16: photoacid generators | C16: surfactant | D16: Top antireflective coatings | E16: polymer | F16: immersion topcoat | G16: PBO/PI | H16: Dev_total | L16: photoacid generators | M16: surfactant | N16: Top antireflective coatings | O16: polymer | P16: immersion topcoat | Q16: PBO/PI | R16: Dev_total | V16: photoacid generators | W16: surfactant | X16: Top antireflective coatings | Y16: polymer | Z16: immersion topcoat | AA16: PBO/PI | AB16: Dev_total
A17: 2020 | K17: 2020 | U17: 2020
A18: 2020.25 | K18: 2020.25 | U18: 2020.25
A19: 2020.5 | K19: 2020.5 | U19: 2020.5
A20: 2020.75 | K20: 2020.75 | U20: 2020.75
A21: 2021 | K21: 2021 | U21: 2021
A22: 2021.25 | K22: 2021.25 | U22: 2021.25
A23: 2021.5 | K23: 2021.5 | U23: 2021.5
A24: 2021.75 | K24: 2021.75 | U24: 2021.75
A25: 2022 | K25: 2022 | U25: 2022
A26: 2022.25 | K26: 2022.25 | U26: 2022.25
A27: 2022.5 | K27: 2022.5 | U27: 2022.5
A28: 2022.75 | K28: 2022.75 | U28: 2022.75
... A36: 2024.75 | K36: 2024.75 | U36: 2024.75
A37: 2025 | B37: =aggressive!B71+aggressive!J71+aggressive!R71+aggressive!Z71 -> 1.6311477 | C37: =aggressive!C71+aggressive!K71+aggressive!S71+aggressive!AA71 -> 0.57663074 | D37: =aggressive!D71+aggressive!L71+aggressive!T71+aggressive!AB71 -> 29.863516 | E37: =aggressive!E71+aggressive!M71+aggressive!U71+aggressive!AC71 -> 0.098724506 | F37: =aggressive!F71+aggressive!N71+aggressive!V71+aggressive!AD71 -> 14.487901 | G37: =aggressive!G71+aggressive!O71+aggressive!W71+aggressive!AE71 -> 0.66022625 | H37: =aggressive!H71+aggressive!P71+aggressive!X71+aggressive!AF71 -> 4.0380976 | K37: 2025 | L37: =moderate!B71+moderate!J71+moderate!R71+moderate!Z71 -> 1.2395562 | M37: =moderate!C71+moderate!K71+moderate!S71+moderate!AA71 -> 0.43819833 | N37: =moderate!D71+moderate!L71+moderate!T71+moderate!AB71 -> 22.690491 | O37: =moderate!E71+moderate!M71+moderate!U71+moderate!AC71 -> 0.0750236 | P37: =moderate!F71+moderate!N71+moderate!V71+moderate!AD71 -> 11.02219 | Q37: =moderate!G71+moderate!O71+moderate!W71+moderate!AE71 -> 0.49687347 | R37: =moderate!H71+moderate!P71+moderate!X71+moderate!AF71 -> 3.1442595 | U37: 2025 | V37: =conservative!B71+conservative!J71+conservative!R71+conservative!Z71 -> 1.0062898 | W37: =conservative!C71+conservative!K71+conservative!S71+conservative!AA71 -> 0.35573581 | X37: =conservative!D71+conservative!L71+conservative!T71+conservative!AB71 -> 18.435842 | Y37: =conservative!E71+conservative!M71+conservative!U71+conservative!AC71 -> 0.060905254 | Z37: =conservative!F71+conservative!N71+conservative!V71+conservative!AD71 -> 8.9620398 | AA37: =conservative!G71+conservative!O71+conservative!W71+conservative!AE71 -> 0.39594645 | AB37: =conservative!H71+conservative!P71+conservative!X71+conservative!AF71 -> 2.6370414
A38: 2025.25 | B38: =aggressive!B72+aggressive!J72+aggressive!R72+aggressive!Z72 -> 1.9856256 | C38: =aggressive!C72+aggressive!K72+aggressive!S72+aggressive!AA72 -> 0.70194301 | D38: =aggressive!D72+aggressive!L72+aggressive!T72+aggressive!AB72 -> 36.251068 | E38: =aggressive!E72+aggressive!M72+aggressive!U72+aggressive!AC72 -> 0.12017912 | F38: =aggressive!F72+aggressive!N72+aggressive!V72+aggressive!AD72 -> 17.637803 | G38: =aggressive!G72+aggressive!O72+aggressive!W72+aggressive!AE72 -> 0.82007443 | H38: =aggressive!H72+aggressive!P72+aggressive!X72+aggressive!AF72 -> 5.0576158 | K38: 2025.25 | L38: =moderate!B72+moderate!J72+moderate!R72+moderate!Z72 -> 1.4829753 | M38: =moderate!C72+moderate!K72+moderate!S72+moderate!AA72 -> 0.52424997 | N38: =moderate!D72+moderate!L72+moderate!T72+moderate!AB72 -> 27.076808 | O38: =moderate!E72+moderate!M72+moderate!U72+moderate!AC72 -> 0.089756435 | P38: =moderate!F72+moderate!N72+moderate!V72+moderate!AD72 -> 13.185221 | Q38: =moderate!G72+moderate!O72+moderate!W72+moderate!AE72 -> 0.60664083 | R38: =moderate!H72+moderate!P72+moderate!X72+moderate!AF72 -> 3.8813852 | U38: 2025.25 | V38: =conservative!B72+conservative!J72+conservative!R72+conservative!Z72 -> 1.1385644 | W38: =conservative!C72+conservative!K72+conservative!S72+conservative!AA72 -> 0.4024965 | X38: =conservative!D72+conservative!L72+conservative!T72+conservative!AB72 -> 20.819378 | Y38: =conservative!E72+conservative!M72+conservative!U72+conservative!AC72 -> 0.068911117 | Z38: =conservative!F72+conservative!N72+conservative!V72+conservative!AD72 -> 10.137436 | AA38: =conservative!G72+conservative!O72+conservative!W72+conservative!AE72 -> 0.45559434 | AB38: =conservative!H72+conservative!P72+conservative!X72+conservative!AF72 -> 3.0616864
A39: 2025.5 | B39: =aggressive!B73+aggressive!J73+aggressive!R73+aggressive!Z73 -> 2.452716 | C39: =aggressive!C73+aggressive!K73+aggressive!S73+aggressive!AA73 -> 0.8670652 | D39: =aggressive!D73+aggressive!L73+aggressive!T73+aggressive!AB73 -> 44.587987 | E39: =aggressive!E73+aggressive!M73+aggressive!U73+aggressive!AC73 -> 0.14844957 | F39: =aggressive!F73+aggressive!N73+aggressive!V73+aggressive!AD73 -> 21.817604 | G39: =aggressive!G73+aggressive!O73+aggressive!W73+aggressive!AE73 -> 1.0350902 | H39: =aggressive!H73+aggressive!P73+aggressive!X73+aggressive!AF73 -> 6.2968815 | K39: 2025.5 | L39: =moderate!B73+moderate!J73+moderate!R73+moderate!Z73 -> 1.7204275 | M39: =moderate!C73+moderate!K73+moderate!S73+moderate!AA73 -> 0.60819224 | N39: =moderate!D73+moderate!L73+moderate!T73+moderate!AB73 -> 31.315002 | O39: =moderate!E73+moderate!M73+moderate!U73+moderate!AC73 -> 0.10412813 | P39: =moderate!F73+moderate!N73+moderate!V73+moderate!AD73 -> 15.310083 | Q39: =moderate!G73+moderate!O73+moderate!W73+moderate!AE73 -> 0.71594725 | R39: =moderate!H73+moderate!P73+moderate!X73+moderate!AF73 -> 4.6301292 | U39: 2025.5 | V39: =conservative!B73+conservative!J73+conservative!R73+conservative!Z73 -> 1.2542712 | W39: =conservative!C73+conservative!K73+conservative!S73+conservative!AA73 -> 0.44340028 | X39: =conservative!D73+conservative!L73+conservative!T73+conservative!AB73 -> 22.884585 | Y39: =conservative!E73+conservative!M73+conservative!U73+conservative!AC73 -> 0.075914221 | Z39: =conservative!F73+conservative!N73+conservative!V73+conservative!AD73 -> 11.172849 | AA39: =conservative!G73+conservative!O73+conservative!W73+conservative!AE73 -> 0.50885766 | AB39: =conservative!H73+conservative!P73+conservative!X73+conservative!AF73 -> 3.4841371
A40: 2025.75 | B40: =aggressive!B74+aggressive!J74+aggressive!R74+aggressive!Z74 -> 2.9168503 | C40: =aggressive!C74+aggressive!K74+aggressive!S74+aggressive!AA74 -> 1.0311424 | D40: =aggressive!D74+aggressive!L74+aggressive!T74+aggressive!AB74 -> 52.795134 | E40: =aggressive!E74+aggressive!M74+aggressive!U74+aggressive!AC74 -> 0.1765411 | F40: =aggressive!F74+aggressive!N74+aggressive!V74+aggressive!AD74 -> 25.999129 | G40: =aggressive!G74+aggressive!O74+aggressive!W74+aggressive!AE74 -> 1.2529746 | H40: =aggressive!H74+aggressive!P74+aggressive!X74+aggressive!AF74 -> 7.7094028 | K40: 2025.75 | L40: =moderate!B74+moderate!J74+moderate!R74+moderate!Z74 -> 1.944181 | M40: =moderate!C74+moderate!K74+moderate!S74+moderate!AA74 -> 0.68729184 | N40: =moderate!D74+moderate!L74+moderate!T74+moderate!AB74 -> 35.271567 | O40: =moderate!E74+moderate!M74+moderate!U74+moderate!AC74 -> 0.11767071 | P40: =moderate!F74+moderate!N74+moderate!V74+moderate!AD74 -> 17.325945 | Q40: =moderate!G74+moderate!O74+moderate!W74+moderate!AE74 -> 0.82098664 | R40: =moderate!H74+moderate!P74+moderate!X74+moderate!AF74 -> 5.3394226 | U40: 2025.75 | V40: =conservative!B74+conservative!J74+conservative!R74+conservative!Z74 -> 1.3800529 | W40: =conservative!C74+conservative!K74+conservative!S74+conservative!AA74 -> 0.48786563 | X40: =conservative!D74+conservative!L74+conservative!T74+conservative!AB74 -> 25.108743 | Y40: =conservative!E74+conservative!M74+conservative!U74+conservative!AC74 -> 0.0835271 | Z40: =conservative!F74+conservative!N74+conservative!V74+conservative!AD74 -> 12.306053 | AA40: =conservative!G74+conservative!O74+conservative!W74+conservative!AE74 -> 0.56790492 | AB40: =conservative!H74+conservative!P74+conservative!X74+conservative!AF74 -> 3.9231381
A41: 2026 | B41: =aggressive!B75+aggressive!J75+aggressive!R75+aggressive!Z75 -> 3.5373817 | C41: =aggressive!C75+aggressive!K75+aggressive!S75+aggressive!AA75 -> 1.2505078 | D41: =aggressive!D75+aggressive!L75+aggressive!T75+aggressive!AB75 -> 63.667841 | E41: =aggressive!E75+aggressive!M75+aggressive!U75+aggressive!AC75 -> 0.21409849 | F41: =aggressive!F75+aggressive!N75+aggressive!V75+aggressive!AD75 -> 31.626252 | G41: =aggressive!G75+aggressive!O75+aggressive!W75+aggressive!AE75 -> 1.5497681 | H41: =aggressive!H75+aggressive!P75+aggressive!X75+aggressive!AF75 -> 9.3783999 | K41: 2026 | L41: =moderate!B75+moderate!J75+moderate!R75+moderate!Z75 -> 2.2711643 | M41: =moderate!C75+moderate!K75+moderate!S75+moderate!AA75 -> 0.80288444 | N41: =moderate!D75+moderate!L75+moderate!T75+moderate!AB75 -> 41.000839 | O41: =moderate!E75+moderate!M75+moderate!U75+moderate!AC75 -> 0.13746123 | P41: =moderate!F75+moderate!N75+moderate!V75+moderate!AD75 -> 20.291106 | Q41: =moderate!G75+moderate!O75+moderate!W75+moderate!AE75 -> 0.97737924 | R41: =moderate!H75+moderate!P75+moderate!X75+moderate!AF75 -> 6.2346734 | U41: 2026 | V41: =conservative!B75+conservative!J75+conservative!R75+conservative!Z75 -> 1.5192371 | W41: =conservative!C75+conservative!K75+conservative!S75+conservative!AA75 -> 0.53706896 | X41: =conservative!D75+conservative!L75+conservative!T75+conservative!AB75 -> 27.547475 | Y41: =conservative!E75+conservative!M75+conservative!U75+conservative!AC75 -> 0.091951164 | Z41: =conservative!F75+conservative!N75+conservative!V75+conservative!AD75 -> 13.568208 | AA41: =conservative!G75+conservative!O75+conservative!W75+conservative!AE75 -> 0.63447524 | AB41: =conservative!H75+conservative!P75+conservative!X75+conservative!AF75 -> 4.3865731
A42: 2026.25 | B42: =aggressive!B76+aggressive!J76+aggressive!R76+aggressive!Z76 -> 4.1562268 | C42: =aggressive!C76+aggressive!K76+aggressive!S76+aggressive!AA76 -> 1.4692772 | D42: =aggressive!D76+aggressive!L76+aggressive!T76+aggressive!AB76 -> 74.474675 | E42: =aggressive!E76+aggressive!M76+aggressive!U76+aggressive!AC76 -> 0.25155382 | F42: =aggressive!F76+aggressive!N76+aggressive!V76+aggressive!AD76 -> 37.243777 | G42: =aggressive!G76+aggressive!O76+aggressive!W76+aggressive!AE76 -> 1.8432237 | H42: =aggressive!H76+aggressive!P76+aggressive!X76+aggressive!AF76 -> 11.305268 | K42: 2026.25 | L42: =moderate!B76+moderate!J76+moderate!R76+moderate!Z76 -> 2.5238239 | M42: =moderate!C76+moderate!K76+moderate!S76+moderate!AA76 -> 0.89220274 | N42: =moderate!D76+moderate!L76+moderate!T76+moderate!AB76 -> 45.413011 | O42: =moderate!E76+moderate!M76+moderate!U76+moderate!AC76 -> 0.15275335 | P42: =moderate!F76+moderate!N76+moderate!V76+moderate!AD76 -> 22.584607 | Q42: =moderate!G76+moderate!O76+moderate!W76+moderate!AE76 -> 1.0971901 | R42: =moderate!H76+moderate!P76+moderate!X76+moderate!AF76 -> 7.1147485 | U42: 2026.25 | V42: =conservative!B76+conservative!J76+conservative!R76+conservative!Z76 -> 1.6618924 | W42: =conservative!C76+conservative!K76+conservative!S76+conservative!AA76 -> 0.58749936 | X42: =conservative!D76+conservative!L76+conservative!T76+conservative!AB76 -> 30.038651 | Y42: =conservative!E76+conservative!M76+conservative!U76+conservative!AC76 -> 0.10058531 | Z42: =conservative!F76+conservative!N76+conservative!V76+conservative!AD76 -> 14.863152 | AA42: =conservative!G76+conservative!O76+conservative!W76+conservative!AE76 -> 0.70212218 | AB42: =conservative!H76+conservative!P76+conservative!X76+conservative!AF76 -> 4.8780019
A43: 2026.5 | B43: =aggressive!B77+aggressive!J77+aggressive!R77+aggressive!Z77 -> 4.9679385 | C43: =aggressive!C77+aggressive!K77+aggressive!S77+aggressive!AA77 -> 1.7562273 | D43: =aggressive!D77+aggressive!L77+aggressive!T77+aggressive!AB77 -> 88.603273 | E43: =aggressive!E77+aggressive!M77+aggressive!U77+aggressive!AC77 -> 0.30068232 | F43: =aggressive!F77+aggressive!N77+aggressive!V77+aggressive!AD77 -> 44.619281 | G43: =aggressive!G77+aggressive!O77+aggressive!W77+aggressive!AE77 -> 2.2249135 | H43: =aggressive!H77+aggressive!P77+aggressive!X77+aggressive!AF77 -> 13.413119 | K43: 2026.5 | L43: =moderate!B77+moderate!J77+moderate!R77+moderate!Z77 -> 3.0293649 | M43: =moderate!C77+moderate!K77+moderate!S77+moderate!AA77 -> 1.0709177 | N43: =moderate!D77+moderate!L77+moderate!T77+moderate!AB77 -> 54.212422 | O43: =moderate!E77+moderate!M77+moderate!U77+moderate!AC77 -> 0.18335099 | P43: =moderate!F77+moderate!N77+moderate!V77+moderate!AD77 -> 27.178134 | Q43: =moderate!G77+moderate!O77+moderate!W77+moderate!AE77 -> 1.3349098 | R43: =moderate!H77+moderate!P77+moderate!X77+moderate!AF77 -> 8.2935626 | U43: 2026.5 | V43: =conservative!B77+conservative!J77+conservative!R77+conservative!Z77 -> 1.8816327 | W43: =conservative!C77+conservative!K77+conservative!S77+conservative!AA77 -> 0.66518026 | X43: =conservative!D77+conservative!L77+conservative!T77+conservative!AB77 -> 33.863435 | Y43: =conservative!E77+conservative!M77+conservative!U77+conservative!AC77 -> 0.113885 | Z43: =conservative!F77+conservative!N77+conservative!V77+conservative!AD77 -> 16.859792 | AA43: =conservative!G77+conservative!O77+conservative!W77+conservative!AE77 -> 0.80545032 | AB43: =conservative!H77+conservative!P77+conservative!X77+conservative!AF77 -> 5.4600363
A44: 2026.75 | B44: =aggressive!B78+aggressive!J78+aggressive!R78+aggressive!Z78 -> 5.8719693 | C44: =aggressive!C78+aggressive!K78+aggressive!S78+aggressive!AA78 -> 2.0758132 | D44: =aggressive!D78+aggressive!L78+aggressive!T78+aggressive!AB78 -> 104.28876 | E44: =aggressive!E78+aggressive!M78+aggressive!U78+aggressive!AC78 -> 0.35539839 | F44: =aggressive!F78+aggressive!N78+aggressive!V78+aggressive!AD78 -> 52.841466 | G44: =aggressive!G78+aggressive!O78+aggressive!W78+aggressive!AE78 -> 2.6465293 | H44: =aggressive!H78+aggressive!P78+aggressive!X78+aggressive!AF78 -> 16.157891 | K44: 2026.75 | L44: =moderate!B78+moderate!J78+moderate!R78+moderate!Z78 -> 3.5810294 | M44: =moderate!C78+moderate!K78+moderate!S78+moderate!AA78 -> 1.2659379 | N44: =moderate!D78+moderate!L78+moderate!T78+moderate!AB78 -> 63.784137 | O44: =moderate!E78+moderate!M78+moderate!U78+moderate!AC78 -> 0.21674025 | P44: =moderate!F78+moderate!N78+moderate!V78+moderate!AD78 -> 32.195538 | Q44: =moderate!G78+moderate!O78+moderate!W78+moderate!AE78 -> 1.5921914 | R44: =moderate!H78+moderate!P78+moderate!X78+moderate!AF78 -> 9.8421749 | U44: 2026.75 | V44: =conservative!B78+conservative!J78+conservative!R78+conservative!Z78 -> 2.1458383 | W44: =conservative!C78+conservative!K78+conservative!S78+conservative!AA78 -> 0.75858018 | X44: =conservative!D78+conservative!L78+conservative!T78+conservative!AB78 -> 38.447563 | Y44: =conservative!E78+conservative!M78+conservative!U78+conservative!AC78 -> 0.12987593 | Z44: =conservative!F78+conservative!N78+conservative!V78+conservative!AD78 -> 19.262749 | AA44: =conservative!G78+conservative!O78+conservative!W78+conservative!AE78 -> 0.92866875 | AB44: =conservative!H78+conservative!P78+conservative!X78+conservative!AF78 -> 6.1646788
A45: 2027 | B45: =aggressive!B79+aggressive!J79+aggressive!R79+aggressive!Z79 -> 7.0529279 | C45: =aggressive!C79+aggressive!K79+aggressive!S79+aggressive!AA79 -> 2.4932966 | D45: =aggressive!D79+aggressive!L79+aggressive!T79+aggressive!AB79 -> 124.71564 | E45: =aggressive!E79+aggressive!M79+aggressive!U79+aggressive!AC79 -> 0.42687539 | F45: =aggressive!F79+aggressive!N79+aggressive!V79+aggressive!AD79 -> 63.592261 | G45: =aggressive!G79+aggressive!O79+aggressive!W79+aggressive!AE79 -> 3.1928742 | H45: =aggressive!H79+aggressive!P79+aggressive!X79+aggressive!AF79 -> 19.36282 | K45: 2027 | L45: =moderate!B79+moderate!J79+moderate!R79+moderate!Z79 -> 4.23061 | M45: =moderate!C79+moderate!K79+moderate!S79+moderate!AA79 -> 1.4955726 | N45: =moderate!D79+moderate!L79+moderate!T79+moderate!AB79 -> 75.019846 | O45: =moderate!E79+moderate!M79+moderate!U79+moderate!AC79 -> 0.25605583 | P45: =moderate!F79+moderate!N79+moderate!V79+moderate!AD79 -> 38.108961 | Q45: =moderate!G79+moderate!O79+moderate!W79+moderate!AE79 -> 1.8927058 | R45: =moderate!H79+moderate!P79+moderate!X79+moderate!AF79 -> 11.605262 | U45: 2027 | V45: =conservative!B79+conservative!J79+conservative!R79+conservative!Z79 -> 2.4438033 | W45: =conservative!C79+conservative!K79+conservative!S79+conservative!AA79 -> 0.86391446 | X45: =conservative!D79+conservative!L79+conservative!T79+conservative!AB79 -> 43.601423 | Y45: =conservative!E79+conservative!M79+conservative!U79+conservative!AC79 -> 0.14791013 | Z45: =conservative!F79+conservative!N79+conservative!V79+conservative!AD79 -> 21.975258 | AA45: =conservative!G79+conservative!O79+conservative!W79+conservative!AE79 -> 1.0665158 | AB45: =conservative!H79+conservative!P79+conservative!X79+conservative!AF79 -> 6.9376059
A46: 2027.25 | B46: =aggressive!B80+aggressive!J80+aggressive!R80+aggressive!Z80 -> 8.4280073 | C46: =aggressive!C80+aggressive!K80+aggressive!S80+aggressive!AA80 -> 2.979404 | D46: =aggressive!D80+aggressive!L80+aggressive!T80+aggressive!AB80 -> 148.42839 | E46: =aggressive!E80+aggressive!M80+aggressive!U80+aggressive!AC80 -> 0.51010148 | F46: =aggressive!F80+aggressive!N80+aggressive!V80+aggressive!AD80 -> 76.121477 | G46: =aggressive!G80+aggressive!O80+aggressive!W80+aggressive!AE80 -> 3.8240205 | H46: =aggressive!H80+aggressive!P80+aggressive!X80+aggressive!AF80 -> 23.192126 | K46: 2027.25 | L46: =moderate!B80+moderate!J80+moderate!R80+moderate!Z80 -> 5.1152669 | M46: =moderate!C80+moderate!K80+moderate!S80+moderate!AA80 -> 1.8083096 | N46: =moderate!D80+moderate!L80+moderate!T80+moderate!AB80 -> 90.275435 | O46: =moderate!E80+moderate!M80+moderate!U80+moderate!AC80 -> 0.30959931 | P46: =moderate!F80+moderate!N80+moderate!V80+moderate!AD80 -> 46.169628 | Q46: =moderate!G80+moderate!O80+moderate!W80+moderate!AE80 -> 2.2987535 | R46: =moderate!H80+moderate!P80+moderate!X80+moderate!AF80 -> 13.990048 | U46: 2027.25 | V46: =conservative!B80+conservative!J80+conservative!R80+conservative!Z80 -> 2.8044811 | W46: =conservative!C80+conservative!K80+conservative!S80+conservative!AA80 -> 0.99141849 | X46: =conservative!D80+conservative!L80+conservative!T80+conservative!AB80 -> 49.821182 | Y46: =conservative!E80+conservative!M80+conservative!U80+conservative!AC80 -> 0.16974 | Z46: =conservative!F80+conservative!N80+conservative!V80+conservative!AD80 -> 25.261621 | AA46: =conservative!G80+conservative!O80+conservative!W80+conservative!AE80 -> 1.2320629 | AB46: =conservative!H80+conservative!P80+conservative!X80+conservative!AF80 -> 7.8432926
A47: 2027.5 | B47: =aggressive!B81+aggressive!J81+aggressive!R81+aggressive!Z81 -> 10.136012 | C47: =aggressive!C81+aggressive!K81+aggressive!S81+aggressive!AA81 -> 3.5832046 | D47: =aggressive!D81+aggressive!L81+aggressive!T81+aggressive!AB81 -> 177.79558 | E47: =aggressive!E81+aggressive!M81+aggressive!U81+aggressive!AC81 -> 0.6134777 | F47: =aggressive!F81+aggressive!N81+aggressive!V81+aggressive!AD81 -> 91.697773 | G47: =aggressive!G81+aggressive!O81+aggressive!W81+aggressive!AE81 -> 4.6019323 | H47: =aggressive!H81+aggressive!P81+aggressive!X81+aggressive!AF81 -> 27.944238 | K47: 2027.5 | L47: =moderate!B81+moderate!J81+moderate!R81+moderate!Z81 -> 6.51177 | M47: =moderate!C81+moderate!K81+moderate!S81+moderate!AA81 -> 2.3019906 | N47: =moderate!D81+moderate!L81+moderate!T81+moderate!AB81 -> 114.28672 | O47: =moderate!E81+moderate!M81+moderate!U81+moderate!AC81 -> 0.39412205 | P47: =moderate!F81+moderate!N81+moderate!V81+moderate!AD81 -> 58.90516 | Q47: =moderate!G81+moderate!O81+moderate!W81+moderate!AE81 -> 2.9347918 | R47: =moderate!H81+moderate!P81+moderate!X81+moderate!AF81 -> 17.508949 | U47: 2027.5 | V47: =conservative!B81+conservative!J81+conservative!R81+conservative!Z81 -> 3.2715549 | W47: =conservative!C81+conservative!K81+conservative!S81+conservative!AA81 -> 1.1565348 | X47: =conservative!D81+conservative!L81+conservative!T81+conservative!AB81 -> 57.851986 | Y47: =conservative!E81+conservative!M81+conservative!U81+conservative!AC81 -> 0.19800944 | Z47: =conservative!F81+conservative!N81+conservative!V81+conservative!AD81 -> 29.521141 | AA47: =conservative!G81+conservative!O81+conservative!W81+conservative!AE81 -> 1.444792 | AB47: =conservative!H81+conservative!P81+conservative!X81+conservative!AF81 -> 9.0739906
A48: 2027.75 | B48: =aggressive!B82+aggressive!J82+aggressive!R82+aggressive!Z82 -> 10.907695 | C48: =aggressive!C82+aggressive!K82+aggressive!S82+aggressive!AA82 -> 3.856004 | D48: =aggressive!D82+aggressive!L82+aggressive!T82+aggressive!AB82 -> 191.02569 | E48: =aggressive!E82+aggressive!M82+aggressive!U82+aggressive!AC82 -> 0.66018348 | F48: =aggressive!F82+aggressive!N82+aggressive!V82+aggressive!AD82 -> 98.741174 | G48: =aggressive!G82+aggressive!O82+aggressive!W82+aggressive!AE82 -> 4.9507403 | H48: =aggressive!H82+aggressive!P82+aggressive!X82+aggressive!AF82 -> 31.557085 | K48: 2027.75 | L48: =moderate!B82+moderate!J82+moderate!R82+moderate!Z82 -> 6.7712272 | M48: =moderate!C82+moderate!K82+moderate!S82+moderate!AA82 -> 2.3937119 | N48: =moderate!D82+moderate!L82+moderate!T82+moderate!AB82 -> 118.73498 | O48: =moderate!E82+moderate!M82+moderate!U82+moderate!AC82 -> 0.40982558 | P48: =moderate!F82+moderate!N82+moderate!V82+moderate!AD82 -> 61.27331 | Q48: =moderate!G82+moderate!O82+moderate!W82+moderate!AE82 -> 3.052069 | R48: =moderate!H82+moderate!P82+moderate!X82+moderate!AF82 -> 19.689482 | U48: 2027.75 | V48: =conservative!B82+conservative!J82+conservative!R82+conservative!Z82 -> 3.5469283 | W48: =conservative!C82+conservative!K82+conservative!S82+conservative!AA82 -> 1.2538827 | X48: =conservative!D82+conservative!L82+conservative!T82+conservative!AB82 -> 62.57312 | Y48: =conservative!E82+conservative!M82+conservative!U82+conservative!AC82 -> 0.21467629 | Z48: =conservative!F82+conservative!N82+conservative!V82+conservative!AD82 -> 32.034563 | AA48: =conservative!G82+conservative!O82+conservative!W82+conservative!AE82 -> 1.5692634 | AB48: =conservative!H82+conservative!P82+conservative!X82+conservative!AF82 -> 10.04704
... A60: 2030.75 | B60: =aggressive!B94+aggressive!J94+aggressive!R94+aggressive!Z94 -> 38.460169 | C60: =aggressive!C94+aggressive!K94+aggressive!S94+aggressive!AA94 -> 13.596142 | D60: =aggressive!D94+aggressive!L94+aggressive!T94+aggressive!AB94 -> 686.24424 | E60: =aggressive!E94+aggressive!M94+aggressive!U94+aggressive!AC94 -> 2.327785 | F60: =aggressive!F94+aggressive!N94+aggressive!V94+aggressive!AD94 -> 349.51007 | G60: =aggressive!G94+aggressive!O94+aggressive!W94+aggressive!AE94 -> 19.673731 | H60: =aggressive!H94+aggressive!P94+aggressive!X94+aggressive!AF94 -> 118.02913 | K60: 2030.75 | L60: =moderate!B94+moderate!J94+moderate!R94+moderate!Z94 -> 24.162285 | M60: =moderate!C94+moderate!K94+moderate!S94+moderate!AA94 -> 8.5416642 | N60: =moderate!D94+moderate!L94+moderate!T94+moderate!AB94 -> 431.14776 | O60: =moderate!E94+moderate!M94+moderate!U94+moderate!AC94 -> 1.4624118 | P60: =moderate!F94+moderate!N94+moderate!V94+moderate!AD94 -> 219.56444 | Q60: =moderate!G94+moderate!O94+moderate!W94+moderate!AE94 -> 12.328773 | R60: =moderate!H94+moderate!P94+moderate!X94+moderate!AF94 -> 73.867382 | U60: 2030.75 | V60: =conservative!B94+conservative!J94+conservative!R94+conservative!Z94 -> 11.092712 | W60: =conservative!C94+conservative!K94+conservative!S94+conservative!AA94 -> 3.9214099 | X60: =conservative!D94+conservative!L94+conservative!T94+conservative!AB94 -> 197.92242 | Y60: =conservative!E94+conservative!M94+conservative!U94+conservative!AC94 -> 0.67138158 | Z60: =conservative!F94+conservative!N94+conservative!V94+conservative!AD94 -> 100.72302 | AA60: =conservative!G94+conservative!O94+conservative!W94+conservative!AE94 -> 5.5744799 | AB60: =conservative!H94+conservative!P94+conservative!X94+conservative!AF94 -> 32.383278
G61: =SUM(B60:G60) -> 1109.8121
B66: aggressive, same unit
...

Sheet aggressive
A1: Ton PFAS | B1: Aggressive | C1: Water | J1: solid | R1: GAS | Z1: Solvent
A2: Cumulative | B2: =[4]Manu_water!R1 -> photoacid generators | C2: =[4]Manu_water!S1 -> surfactant | D2: =[4]Manu_water!T1 -> Top antireflective coatings | E2: =[4]Manu_water!U1 -> polymer | F2: =[4]Manu_water!V1 -> immersion topcoat | G2: =[4]Manu_water!W1 -> PBO/PI | H2: Dev_total | J2: =[4]Manu_solid!R1 -> photoacid generators | K2: =[4]Manu_solid!S1 -> surfactant | L2: =[4]Manu_solid!T1 -> Top antireflective coatings | M2: =[4]Manu_solid!U1 -> polymer | N2: =[4]Manu_solid!V1 -> immersion topcoat | O2: =[4]Manu_solid!W1 -> PBO/PI | P2: Dev_total | R2: =[4]Manu_gas!R1 -> photoacid generators | S2: =[4]Manu_gas!S1 -> surfactant | T2: =[4]Manu_gas!T1 -> Top antireflective coatings | U2: =[4]Manu_gas!U1 -> polymer | V2: =[4]Manu_gas!V1 -> immersion topcoat | W2: =[4]Manu_gas!W1 -> PBO/PI | X2: Dev_total | Z2: =[4]Manu_solvent!R1 -> photoacid generators | AA2: =[4]Manu_solvent!S1 -> surfactant | AB2: =[4]Manu_solvent!T1 -> Top antireflective coatings | AC2: =[4]Manu_solvent!U1 -> polymer | AD2: =[4]Manu_solvent!V1 -> immersion topcoat | AE2: =[4]Manu_solvent!W1 -> PBO/PI | AF2: Dev_total
A3: 2020 | B3: =[4]Manu_water!R2 -> 0.0056519089 | C3: =[4]Manu_water!S2 -> 0.0044960884 | D3: =[4]Manu_water!T2 -> 0.20021512 | E3: =[4]Manu_water!U2 -> 0.00028561619 | F3: =[4]Manu_water!V2 -> 0.12233688 | G3: =[4]Manu_water!W2 -> 0.00092897713 | H3: =SUM([4]Manu_water!$X2:$AC2) -> 0.02728346 | J3: =[4]Manu_solid!R2 -> 0.0013885313 | K3: =[4]Manu_solid!S2 -> 1.4075411e-05 | L3: =[4]Manu_solid!T2 -> 0.00070912909 | M3: =[4]Manu_solid!U2 -> 9.8557698e-05 | N3: =[4]Manu_solid!V2 -> 0.00021314194 | O3: =[4]Manu_solid!W2 -> 0.00076409374 | P3: =SUM([4]Manu_solid!$X2:$AC2) -> 0.00026044631 | R3: =[4]Manu_gas!R2 -> 0.0028748464 | S3: =[4]Manu_gas!S2 -> 0 | T3: =[4]Manu_gas!T2 -> 0 | U3: =[4]Manu_gas!U2 -> 0.00019510401 | V3: =[4]Manu_gas!V2 -> 0 | W3: =[4]Manu_gas!W2 -> 0 | X3: =SUM([4]Manu_gas!$X2:$AC2) -> 0.0002508392 | Z3: =[4]Manu_solvent!R2 -> 0.18559383 | AA3: =[4]Manu_solvent!S2 -> 9.4506331e-05 | AB3: =[4]Manu_solvent!T2 -> 0.022640085 | AC3: =[4]Manu_solvent!U2 -> 0.012711932 | AD3: =[4]Manu_solvent!V2 -> 0.032554415 | AE3: =[4]Manu_solvent!W2 -> 0.079089735 | AF3: =SUM([4]Manu_solvent!$X2:$AC2) -> 0.027182952
A4: 2020.25 | B4: =[4]Manu_water!R3 -> 0.010113684 | C4: =[4]Manu_water!S3 -> 0.0080454267 | D4: =[4]Manu_water!T3 -> 0.35827054 | E4: =[4]Manu_water!U3 -> 0.00051108961 | F4: =[4]Manu_water!V3 -> 0.21891305 | G4: =[4]Manu_water!W3 -> 0.0016623377 | H4: =SUM([4]Manu_water!$X3:$AC3) -> 0.045252543 | J4: =[4]Manu_solid!R3 -> 0.0024846768 | K4: =[4]Manu_solid!S3 -> 2.5186935e-05 | L4: =[4]Manu_solid!T3 -> 0.0012689355 | M4: =[4]Manu_solid!U3 -> 0.00017636191 | N4: =[4]Manu_solid!V3 -> 0.00038140216 | O4: =[4]Manu_solid!W3 -> 0.0013672908 | P4: =SUM([4]Manu_solid!$X3:$AC3) -> 0.00043197812 | R4: =[4]Manu_gas!R3 -> 0.0051443307 | S4: =[4]Manu_gas!S3 -> 0 | T4: =[4]Manu_gas!T3 -> 0 | U4: =[4]Manu_gas!U3 -> 0.00034912459 | V4: =[4]Manu_gas!V3 -> 0 | W4: =[4]Manu_gas!W3 -> 0 | X4: =SUM([4]Manu_gas!$X3:$AC3) -> 0.0004160437 | Z4: =[4]Manu_solvent!R3 -> 0.33210679 | AA4: =[4]Manu_solvent!S3 -> 0.00016911228 | AB4: =[4]Manu_solvent!T3 -> 0.040512802 | AC4: =[4]Manu_solvent!U3 -> 0.022747087 | AD4: =[4]Manu_solvent!V3 -> 0.058253783 | AE4: =[4]Manu_solvent!W3 -> 0.14152539 | AF4: =SUM([4]Manu_solvent!$X3:$AC3) -> 0.045085839
A5: 2020.5 | B5: =[4]Manu_water!R4 -> 0.017561453 | C5: =[4]Manu_water!S4 -> 0.01397012 | D5: =[4]Manu_water!T4 -> 0.62210281 | E5: =[4]Manu_water!U4 -> 0.00088745861 | F5: =[4]Manu_water!V4 -> 0.38012174 | G5: =[4]Manu_water!W4 -> 0.0028864917 | H5: =SUM([4]Manu_water!$X4:$AC4) -> 0.071406101 | J5: =[4]Manu_solid!R4 -> 0.0043144054 | K5: =[4]Manu_solid!S4 -> 4.3734723e-05 | L5: =[4]Manu_solid!T4 -> 0.0022033861 | M5: =[4]Manu_solid!U4 -> 0.00030623572 | N5: =[4]Manu_solid!V4 -> 0.00066226866 | O5: =[4]Manu_solid!W4 -> 0.0023741707 | P5: =SUM([4]Manu_solid!$X4:$AC4) -> 0.00068163846 | R5: =[4]Manu_gas!R4 -> 0.0089326422 | S5: =[4]Manu_gas!S4 -> 0 | T5: =[4]Manu_gas!T4 -> 0 | U5: =[4]Manu_gas!U4 -> 0.00060622173 | V5: =[4]Manu_gas!V4 -> 0 | W5: =[4]Manu_gas!W4 -> 0 | X5: =SUM([4]Manu_gas!$X4:$AC4) -> 0.00065649479 | Z5: =[4]Manu_solvent!R4 -> 0.57667194 | AA5: =[4]Manu_solvent!S4 -> 0.00029364743 | AB5: =[4]Manu_solvent!T4 -> 0.070346637 | AC5: =[4]Manu_solvent!U4 -> 0.039498158 | AD5: =[4]Manu_solvent!V4 -> 0.10115217 | AE5: =[4]Manu_solvent!W4 -> 0.24574541 | AF5: =SUM([4]Manu_solvent!$X4:$AC4) -> 0.071143051
A6: 2020.75 | B6: =[4]Manu_water!R5 -> 0.029831031 | C6: =[4]Manu_water!S5 -> 0.023730558 | D6: =[4]Manu_water!T5 -> 1.0567444 | E6: =[4]Manu_water!U5 -> 0.0015074951 | F6: =[4]Manu_water!V5 -> 0.6456996 | G6: =[4]Manu_water!W5 -> 0.0049031832 | H6: =SUM([4]Manu_water!$X5:$AC5) -> 0.10848662 | J6: =[4]Manu_solid!R5 -> 0.0073287307 | K6: =[4]Manu_solid!S5 -> 7.4290655e-05 | L6: =[4]Manu_solid!T5 -> 0.0037428154 | M6: =[4]Manu_solid!U5 -> 0.00052019198 | N6: =[4]Manu_solid!V5 -> 0.0011249728 | O6: =[4]Manu_solid!W5 -> 0.0040329213 | P6: =SUM([4]Manu_solid!$X5:$AC5) -> 0.001035607 | R6: =[4]Manu_gas!R5 -> 0.015173569 | S6: =[4]Manu_gas!S5 -> 0 | T6: =[4]Manu_gas!T5 -> 0 | U6: =[4]Manu_gas!U5 -> 0.0010297678 | V6: =[4]Manu_gas!V5 -> 0 | W6: =[4]Manu_gas!W5 -> 0 | X6: =SUM([4]Manu_gas!$X5:$AC5) -> 0.00099740642 | Z6: =[4]Manu_solvent!R5 -> 0.97957259 | AA6: =[4]Manu_solvent!S5 -> 0.00049880868 | AB6: =[4]Manu_solvent!T5 -> 0.11949539 | AC6: =[4]Manu_solvent!U5 -> 0.067094149 | AD6: =[4]Manu_solvent!V5 -> 0.17182367 | AE6: =[4]Manu_solvent!W5 -> 0.41743919 | AF6: =SUM([4]Manu_solvent!$X5:$AC5) -> 0.10808697
A7: 2021 | B7: =[4]Manu_water!R6 -> 0.0493869 | C7: =[4]Manu_water!S6 -> 0.039287234 | D7: =[4]Manu_water!T6 -> 1.7494981 | E7: =[4]Manu_water!U6 -> 0.0024957405 | F7: =[4]Manu_water!V6 -> 1.0689909 | G7: =[4]Manu_water!W6 -> 0.0081174876 | H7: =SUM([4]Manu_water!$X6:$AC6) -> 0.1598982 | J7: =[4]Manu_solid!R6 -> 0.012133114 | K7: =[4]Manu_solid!S6 -> 0.00012299224 | L7: =[4]Manu_solid!T6 -> 0.0061964353 | M7: =[4]Manu_solid!U6 -> 0.00086120623 | N7: =[4]Manu_solid!V6 -> 0.0018624539 | O7: =[4]Manu_solid!W6 -> 0.0066767214 | P7: =SUM([4]Manu_solid!$X6:$AC6) -> 0.0015263789 | R7: =[4]Manu_gas!R6 -> 0.025120672 | S7: =[4]Manu_gas!S6 -> 0 | T7: =[4]Manu_gas!T6 -> 0 | U7: =[4]Manu_gas!U6 -> 0.0017048368 | V7: =[4]Manu_gas!V6 -> 0 | W7: =[4]Manu_gas!W6 -> 0 | X7: =SUM([4]Manu_gas!$X6:$AC6) -> 0.0014700752 | Z7: =[4]Manu_solvent!R6 -> 1.6217359 | AA7: =[4]Manu_solvent!S6 -> 0.00082580502 | AB7: =[4]Manu_solvent!T6 -> 0.19783114 | AC7: =[4]Manu_solvent!U6 -> 0.11107803 | AD7: =[4]Manu_solvent!V6 -> 0.28446347 | AE7: =[4]Manu_solvent!W6 -> 0.69109338 | AF7: =SUM([4]Manu_solvent!$X6:$AC6) -> 0.15930916
A8: 2021.25 | B8: =[4]Manu_water!R7 -> 0.10396679 | C8: =[4]Manu_water!S7 -> 0.082705487 | D8: =[4]Manu_water!T7 -> 3.7277364 | E8: =[4]Manu_water!U7 -> 0.005253906 | F8: =[4]Manu_water!V7 -> 2.2386706 | G8: =[4]Manu_water!W7 -> 0.01721334 | H8: =SUM([4]Manu_water!$X7:$AC7) -> 0.36041803 | J8: =[4]Manu_solid!R7 -> 0.025542014 | K8: =[4]Manu_solid!S7 -> 0.000258917 | L8: =[4]Manu_solid!T7 -> 0.013203031 | M8: =[4]Manu_solid!U7 -> 0.0018129676 | N8: =[4]Manu_solid!V7 -> 0.0039003331 | O8: =[4]Manu_solid!W7 -> 0.014158159 | P8: =SUM([4]Manu_solid!$X7:$AC7) -> 0.0034358524 | R8: =[4]Manu_gas!R7 -> 0.052882762 | S8: =[4]Manu_gas!S7 -> 0 | T8: =[4]Manu_gas!T7 -> 0 | U8: =[4]Manu_gas!U7 -> 0.0035889358 | V8: =[4]Manu_gas!V7 -> 0 | W8: =[4]Manu_gas!W7 -> 0 | X8: =SUM([4]Manu_gas!$X7:$AC7) -> 0.0032948351 | Z8: =[4]Manu_solvent!R7 -> 3.413996 | AA8: =[4]Manu_solvent!S7 -> 0.0017384427 | AB8: =[4]Manu_solvent!T7 -> 0.42152796 | AC8: =[4]Manu_solvent!U7 -> 0.23383581 | AD8: =[4]Manu_solvent!V7 -> 0.59572069 | AE8: =[4]Manu_solvent!W7 -> 1.4654812 | AF8: =SUM([4]Manu_solvent!$X7:$AC7) -> 0.3578287
A9: 2021.5 | B9: =[4]Manu_water!R8 -> 0.21762388 | C9: =[4]Manu_water!S8 -> 0.1731196 | D9: =[4]Manu_water!T8 -> 7.9402938 | E9: =[4]Manu_water!U8 -> 0.010997506 | F9: =[4]Manu_water!V8 -> 4.6500618 | G9: =[4]Manu_water!W8 -> 0.036413959 | H9: =SUM([4]Manu_water!$X8:$AC8) -> 0.84654995 | J9: =[4]Manu_solid!R8 -> 0.053464691 | K9: =[4]Manu_solid!S8 -> 0.00054196656 | L9: =[4]Manu_solid!T8 -> 0.028123218 | M9: =[4]Manu_solid!U8 -> 0.0037949141 | N9: =[4]Manu_solid!V8 -> 0.0081015893 | O9: =[4]Manu_solid!W8 -> 0.029950875 | P9: =SUM([4]Manu_solid!$X8:$AC8) -> 0.0080540117 | R9: =[4]Manu_gas!R8 -> 0.1106945 | S9: =[4]Manu_gas!S8 -> 0 | T9: =[4]Manu_gas!T8 -> 0 | U9: =[4]Manu_gas!U8 -> 0.0075123811 | V9: =[4]Manu_gas!V8 -> 0 | W9: =[4]Manu_gas!W8 -> 0 | X9: =SUM([4]Manu_gas!$X8:$AC8) -> 0.0076741729 | Z9: =[4]Manu_solvent!R8 -> 7.1461961 | AA9: =[4]Manu_solvent!S8 -> 0.0036389183 | AB9: =[4]Manu_solvent!T8 -> 0.89787888 | AC9: =[4]Manu_solvent!U8 -> 0.48946648 | AD9: =[4]Manu_solvent!V8 -> 1.2374031 | AE9: =[4]Manu_solvent!W8 -> 3.100152 | AF9: =SUM([4]Manu_solvent!$X8:$AC8) -> 0.83612001
A10: 2021.75 | B10: =[4]Manu_water!R9 -> 0.31144041 | C10: =[4]Manu_water!S9 -> 0.24775057 | D10: =[4]Manu_water!T9 -> 11.494168 | E10: =[4]Manu_water!U9 -> 0.015738474 | F10: =[4]Manu_water!V9 -> 6.6204485 | G10: =[4]Manu_water!W9 -> 0.052476551 | H10: =SUM([4]Manu_water!$X9:$AC9) -> 1.194756 | J10: =[4]Manu_solid!R9 -> 0.076513043 | K10: =[4]Manu_solid!S9 -> 0.00077560553 | L10: =[4]Manu_solid!T9 -> 0.040710457 | M10: =[4]Manu_solid!U9 -> 0.005430882 | N10: =[4]Manu_solid!V9 -> 0.011534504 | O10: =[4]Manu_solid!W9 -> 0.043162531 | P10: =SUM([4]Manu_solid!$X9:$AC9) -> 0.011354132 | R10: =[4]Manu_gas!R9 -> 0.15841433 | S10: =[4]Manu_gas!S9 -> 0 | T10: =[4]Manu_gas!T9 -> 0 | U10: =[4]Manu_gas!U9 -> 0.01075093 | V10: =[4]Manu_gas!V9 -> 0 | W10: =[4]Manu_gas!W9 -> 0 | X10: =SUM([4]Manu_gas!$X9:$AC9) -> 0.010779796 | Z10: =[4]Manu_solvent!R9 -> 10.226884 | AA10: =[4]Manu_solvent!S9 -> 0.0052076372 | AB10: =[4]Manu_solvent!T9 -> 1.2997467 | AC10: =[4]Manu_solvent!U9 -> 0.70047294 | AD10: =[4]Manu_solvent!V9 -> 1.7617322 | AE10: =[4]Manu_solvent!W9 -> 4.4676627 | AF10: =SUM([4]Manu_solvent!$X9:$AC9) -> 1.1766142
A11: 2022 | B11: =[4]Manu_water!R10 -> 0.51620345 | C11: =[4]Manu_water!S10 -> 0.41063938 | D11: =[4]Manu_water!T10 -> 19.417866 | E11: =[4]Manu_water!U10 -> 0.026086064 | F11: =[4]Manu_water!V10 -> 10.877296 | G11: =[4]Manu_water!W10 -> 0.08800021 | H11: =SUM([4]Manu_water!$X10:$AC10) -> 2.0716217 | J11: =[4]Manu_solid!R10 -> 0.12681815 | K11: =[4]Manu_solid!S10 -> 0.0012855437 | L11: =[4]Manu_solid!T10 -> 0.068774896 | M11: =[4]Manu_solid!U10 -> 0.0090015293 | N11: =[4]Manu_solid!V10 -> 0.018951014 | O11: =[4]Manu_solid!W10 -> 0.072381125 | P11: =SUM([4]Manu_solid!$X10:$AC10) -> 0.019645476 | R11: =[4]Manu_gas!R10 -> 0.26256715 | S11: =[4]Manu_gas!S10 -> 0 | T11: =[4]Manu_gas!T10 -> 0 | U11: =[4]Manu_gas!U10 -> 0.017819354 | V11: =[4]Manu_gas!V10 -> 0 | W11: =[4]Manu_gas!W10 -> 0 | X11: =SUM([4]Manu_gas!$X10:$AC10) -> 0.018523607 | Z11: =[4]Manu_solvent!R10 -> 16.950764 | AA11: =[4]Manu_solvent!S10 -> 0.0086315075 | AB11: =[4]Manu_solvent!T10 -> 2.195749 | AC11: =[4]Manu_solvent!U10 -> 1.1610136 | AD11: =[4]Manu_solvent!V10 -> 2.8944992 | AE11: =[4]Manu_solvent!W10 -> 7.4920179 | AF11: =SUM([4]Manu_solvent!$X10:$AC10) -> 2.028895
A12: 2022.25 | B12: =[4]Manu_water!R11 -> 0.78196941 | C12: =[4]Manu_water!S11 -> 0.62205596 | D12: =[4]Manu_water!T11 -> 29.918593 | E12: =[4]Manu_water!U11 -> 0.039516405 | F12: =[4]Manu_water!V11 -> 16.345733 | G12: =[4]Manu_water!W11 -> 0.13471023 | H12: =SUM([4]Manu_water!$X11:$AC11) -> 3.2431748 | J12: =[4]Manu_solid!R11 -> 0.19211013 | K12: =[4]Manu_solid!S11 -> 0.0019474024 | L12: =[4]Manu_solid!T11 -> 0.10596675 | M12: =[4]Manu_solid!U11 -> 0.013635943 | N12: =[4]Manu_solid!V11 -> 0.02847842 | O12: =[4]Manu_solid!W11 -> 0.11080062 | P12: =SUM([4]Manu_solid!$X11:$AC11) -> 0.03069825 | R12: =[4]Manu_gas!R11 -> 0.39774915 | S12: =[4]Manu_gas!S11 -> 0 | T12: =[4]Manu_gas!T11 -> 0 | U12: =[4]Manu_gas!U11 -> 0.0269936 | V12: =[4]Manu_gas!V11 -> 0 | W12: =[4]Manu_gas!W11 -> 0 | X12: =SUM([4]Manu_gas!$X11:$AC11) -> 0.028769338 | Z12: =[4]Manu_solvent!R11 -> 25.677819 | AA12: =[4]Manu_solvent!S11 -> 0.013075416 | AB12: =[4]Manu_solvent!T11 -> 3.3831585 | AC12: =[4]Manu_solvent!U11 -> 1.7587583 | AD12: =[4]Manu_solvent!V11 -> 4.3496757 | AE12: =[4]Manu_solvent!W11 -> 11.468739 | AF12: =SUM([4]Manu_solvent!$X11:$AC11) -> 3.1608486
A13: 2022.5 | B13: =[4]Manu_water!R12 -> 1.0037766 | C13: =[4]Manu_water!S12 -> 0.79850335 | D13: =[4]Manu_water!T12 -> 38.862721 | E13: =[4]Manu_water!U12 -> 0.05072531 | F13: =[4]Manu_water!V12 -> 20.86251 | G13: =[4]Manu_water!W12 -> 0.17419666 | H13: =SUM([4]Manu_water!$X12:$AC12) -> 4.1742695 | J13: =[4]Manu_solid!R12 -> 0.24660255 | K13: =[4]Manu_solid!S12 -> 0.0024997869 | L13: =[4]Manu_solid!T12 -> 0.13764538 | M13: =[4]Manu_solid!U12 -> 0.017503804 | N13: =[4]Manu_solid!V12 -> 0.036347794 | O13: =[4]Manu_solid!W12 -> 0.14327864 | P13: =SUM([4]Manu_solid!$X12:$AC12) -> 0.039462994 | R13: =[4]Manu_gas!R12 -> 0.51057147 | S13: =[4]Manu_gas!S12 -> 0 | T13: =[4]Manu_gas!T12 -> 0 | U13: =[4]Manu_gas!U12 -> 0.034650388 | V13: =[4]Manu_gas!V12 -> 0 | W13: =[4]Manu_gas!W12 -> 0 | X13: =SUM([4]Manu_gas!$X12:$AC12) -> 0.036833941 | Z13: =[4]Manu_solvent!R12 -> 32.961383 | AA13: =[4]Manu_solvent!S12 -> 0.016784283 | AB13: =[4]Manu_solvent!T12 -> 4.3945498 | AC13: =[4]Manu_solvent!U12 -> 2.2576335 | AD13: =[4]Manu_solvent!V12 -> 5.5516112 | AE13: =[4]Manu_solvent!W12 -> 14.83047 | AF13: =SUM([4]Manu_solvent!$X12:$AC12) -> 4.0552179
A14: 2022.75 | B14: =[4]Manu_water!R13 -> 1.3714938 | C14: =[4]Manu_water!S13 -> 1.0910221 | D14: =[4]Manu_water!T13 -> 53.988796 | E14: =[4]Manu_water!U13 -> 0.069307705 | F14: =[4]Manu_water!V13 -> 28.272503 | G14: =[4]Manu_water!W13 -> 0.24048961 | H14: =SUM([4]Manu_water!$X13:$AC13) -> 5.817121 | J14: =[4]Manu_solid!R13 -> 0.33694139 | K14: =[4]Manu_solid!S13 -> 0.0034155432 | L14: =[4]Manu_solid!T13 -> 0.19121946 | M14: =[4]Manu_solid!U13 -> 0.023916039 | N14: =[4]Manu_solid!V13 -> 0.049257885 | O14: =[4]Manu_solid!W13 -> 0.19780531 | P14: =SUM([4]Manu_solid!$X13:$AC13) -> 0.054894125 | R14: =[4]Manu_gas!R13 -> 0.69761104 | S14: =[4]Manu_gas!S13 -> 0 | T14: =[4]Manu_gas!T13 -> 0 | U14: =[4]Manu_gas!U13 -> 0.047343995 | V14: =[4]Manu_gas!V13 -> 0 | W14: =[4]Manu_gas!W13 -> 0 | X14: =SUM([4]Manu_gas!$X13:$AC13) -> 0.050928242 | Z14: =[4]Manu_solvent!R13 -> 45.03625 | AA14: =[4]Manu_solvent!S13 -> 0.022932933 | AB14: =[4]Manu_solvent!T13 -> 6.1049881 | AC14: =[4]Manu_solvent!U13 -> 3.0846809 | AD14: =[4]Manu_solvent!V13 -> 7.523445 | AE14: =[4]Manu_solvent!W13 -> 20.474411 | AF14: =SUM([4]Manu_solvent!$X13:$AC13) -> 5.624194
... A46: 2030.75 | B46: =[4]Manu_water!R45 -> 546.09272 | C46: =[4]Manu_water!S45 -> 434.41627 | D46: =[4]Manu_water!T45 -> 21851.229 | E46: =[4]Manu_water!U45 -> 27.596503 | F46: =[4]Manu_water!V45 -> 11066.896 | G46: =[4]Manu_water!W45 -> 149.64032 | H46: =SUM([4]Manu_water!$X45:$AC45) -> 3623.8576 | J46: =[4]Manu_solid!R45 -> 134.16119 | K46: =[4]Manu_solid!S45 -> 1.3599794 | L46: =[4]Manu_solid!T45 -> 77.393469 | M46: =[4]Manu_solid!U45 -> 9.5227369 | N46: =[4]Manu_solid!V45 -> 19.281346 | O46: =[4]Manu_solid!W45 -> 123.08078 | P46: =SUM([4]Manu_solid!$X45:$AC45) -> 38.82844 | R46: =[4]Manu_gas!R45 -> 277.77035 | S46: =[4]Manu_gas!S45 -> 0 | T46: =[4]Manu_gas!T45 -> 0 | U46: =[4]Manu_gas!U45 -> 18.851132 | V46: =[4]Manu_gas!V45 -> 0 | W46: =[4]Manu_gas!W45 -> 0 | X46: =SUM([4]Manu_gas!$X45:$AC45) -> 31.546559 | Z46: =[4]Manu_solvent!R45 -> 17932.249 | AA46: =[4]Manu_solvent!S45 -> 9.1312901 | AB46: =[4]Manu_solvent!T45 -> 2470.9108 | AC46: =[4]Manu_solvent!U45 -> 1228.2387 | AD46: =[4]Manu_solvent!V45 -> 2944.9527 | AE46: =[4]Manu_solvent!W45 -> 12739.833 | AF46: =SUM([4]Manu_solvent!$X45:$AC45) -> 3973.0226
A48: Cost
B49: ='Unit-upper left'!$B$8 -> 31.269344 | C49: ='Unit-upper left'!$B$8 -> 31.269344 | D49: ='Unit-upper left'!$B$8 -> 31.269344 | E49: ='Unit-upper left'!$B$8 -> 31.269344 | F49: ='Unit-upper left'!$B$8 -> 31.269344 | G49: ='Unit-upper left'!$B$8 -> 31.269344 | H49: ='Unit-upper left'!$B$8 -> 31.269344 | J49: ='Unit-upper left'!$B$15 -> 1.1657216 | K49: ='Unit-upper left'!$B$15 -> 1.1657216 | L49: ='Unit-upper left'!$B$15 -> 1.1657216 | M49: ='Unit-upper left'!$B$15 -> 1.1657216 | N49: ='Unit-upper left'!$B$15 -> 1.1657216 | O49: ='Unit-upper left'!$B$15 -> 1.1657216 | P49: ='Unit-upper left'!$B$15 -> 1.1657216 | R49: ='Unit-upper left'!$B$15 -> 1.1657216 | S49: ='Unit-upper left'!$B$15 -> 1.1657216 | T49: ='Unit-upper left'!$B$15 -> 1.1657216 | U49: ='Unit-upper left'!$B$15 -> 1.1657216 | V49: ='Unit-upper left'!$B$15 -> 1.1657216 | W49: ='Unit-upper left'!$B$15 -> 1.1657216 | X49: ='Unit-upper left'!$B$15 -> 1.1657216 | Z49: ='Unit-upper left'!$B$15 -> 1.1657216 | AA49: ='Unit-upper left'!$B$15 -> 1.1657216 | AB49: ='Unit-upper left'!$B$15 -> 1.1657216 | AC49: ='Unit-upper left'!$B$15 -> 1.1657216 | AD49: ='Unit-upper left'!$B$15 -> 1.1657216 | AE49: ='Unit-upper left'!$B$15 -> 1.1657216 | AF49: ='Unit-upper left'!$B$15 -> 1.1657216
A50: Unit: million $
A51: 2020 | B51: =1000*B3*B$49/1000000 -> 0.00017673149 | C51: =1000*C3*C$49/1000000 -> 0.00014058974 | D51: =1000*D3*D$49/1000000 -> 0.0062605955 | E51: =1000*E3*E$49/1000000 -> 8.9310309e-06 | F51: =1000*F3*F$49/1000000 -> 0.0038253942 | G51: =1000*G3*G$49/1000000 -> 2.9048506e-05 | H51: =1000*H3*H$49/1000000 -> 0.00085313591 | I51: =1000*I3*I$49/1000000 -> 0 | ... P51: =1000*P3*P$49/1000000 -> 3.0360789e-07 | R51: =1000*R3*R$49/1000000 -> 3.3512706e-06 | S51: =1000*S3*S$49/1000000 -> 0 | T51: =1000*T3*T$49/1000000 -> 0 | U51: =1000*U3*U$49/1000000 -> 2.2743697e-07 | V51: =1000*V3*V$49/1000000 -> 0 | W51: =1000*W3*W$49/1000000 -> 0 | X51: =1000*X3*X$49/1000000 -> 2.9240868e-07 | Z51: =1000*Z3*Z$49/1000000 -> 0.00021635073 | AA51: =1000*AA3*AA$49/1000000 -> 1.1016807e-07 | AB51: =1000*AB3*AB$49/1000000 -> 2.6392036e-05 | AC51: =1000*AC3*AC$49/1000000 -> 1.4818573e-05 | AD51: =1000*AD3*AD$49/1000000 -> 3.7949385e-05 | AE51: =1000*AE3*AE$49/1000000 -> 9.2196613e-05 | AF51: =1000*AF3*AF$49/1000000 -> 3.1687754e-05
A52: 2020.25 | B52: =1000*B4*B$49/1000000 -> 0.00031624828 | C52: =1000*C4*C$49/1000000 -> 0.00025157522 | D52: =1000*D4*D$49/1000000 -> 0.011202885 | E52: =1000*E4*E$49/1000000 -> 1.5981437e-05 | F52: =1000*F4*F$49/1000000 -> 0.0068452675 | G52: =1000*G4*G$49/1000000 -> 5.1980211e-05 | H52: =1000*H4*H$49/1000000 -> 0.0014150174 | I52: =1000*I4*I$49/1000000 -> 0 | ... P52: =1000*P4*P$49/1000000 -> 5.0356623e-07 | R52: =1000*R4*R$49/1000000 -> 5.9968575e-06 | S52: =1000*S4*S$49/1000000 -> 0 | T52: =1000*T4*T$49/1000000 -> 0 | U52: =1000*U4*U$49/1000000 -> 4.0698208e-07 | V52: =1000*V4*V$49/1000000 -> 0 | W52: =1000*W4*W$49/1000000 -> 0 | X52: =1000*X4*X$49/1000000 -> 4.8499113e-07 | Z52: =1000*Z4*Z$49/1000000 -> 0.00038714407 | AA52: =1000*AA4*AA$49/1000000 -> 1.9713784e-07 | AB52: =1000*AB4*AB$49/1000000 -> 4.7226649e-05 | AC52: =1000*AC4*AC$49/1000000 -> 2.6516771e-05 | AD52: =1000*AD4*AD$49/1000000 -> 6.7907693e-05 | AE52: =1000*AE4*AE$49/1000000 -> 0.0001649792 | AF52: =1000*AF4*AF$49/1000000 -> 5.2557537e-05
A53: 2020.5 | B53: =1000*B5*B$49/1000000 -> 0.00054913513 | C53: =1000*C5*C$49/1000000 -> 0.0004368365 | D53: =1000*D5*D$49/1000000 -> 0.019452747 | E53: =1000*E5*E$49/1000000 -> 2.7750249e-05 | F53: =1000*F5*F$49/1000000 -> 0.011886158 | G53: =1000*G5*G$49/1000000 -> 9.0258704e-05 | H53: =1000*H5*H$49/1000000 -> 0.002232822 | I53: =1000*I5*I$49/1000000 -> 0 | ... P53: =1000*P5*P$49/1000000 -> 7.9460068e-07 | R53: =1000*R5*R$49/1000000 -> 1.0412974e-05 | S53: =1000*S5*S$49/1000000 -> 0 | T53: =1000*T5*T$49/1000000 -> 0 | U53: =1000*U5*U$49/1000000 -> 7.0668577e-07 | V53: =1000*V5*V$49/1000000 -> 0 | W53: =1000*W5*W$49/1000000 -> 0 | X53: =1000*X5*X$49/1000000 -> 7.6529016e-07 | Z53: =1000*Z5*Z$49/1000000 -> 0.00067223894 | AA53: =1000*AA5*AA$49/1000000 -> 3.4231115e-07 | AB53: =1000*AB5*AB$49/1000000 -> 8.2004595e-05 | AC53: =1000*AC5*AC$49/1000000 -> 4.6043856e-05 | AD53: =1000*AD5*AD$49/1000000 -> 0.00011791527 | AE53: =1000*AE5*AE$49/1000000 -> 0.00028647073 | AF53: =1000*AF5*AF$49/1000000 -> 8.2932991e-05
A54: 2020.75 | B54: =1000*B6*B$49/1000000 -> 0.00093279677 | C54: =1000*C6*C$49/1000000 -> 0.00074203899 | D54: =1000*D6*D$49/1000000 -> 0.033043706 | E54: =1000*E6*E$49/1000000 -> 4.7138385e-05 | F54: =1000*F6*F$49/1000000 -> 0.020190603 | G54: =1000*G6*G$49/1000000 -> 0.00015331933 | H54: =1000*H6*H$49/1000000 -> 0.0033923056 | I54: =1000*I6*I$49/1000000 -> 0 | ... P54: =1000*P6*P$49/1000000 -> 1.2072294e-06 | R54: =1000*R6*R$49/1000000 -> 1.7688157e-05 | S54: =1000*S6*S$49/1000000 -> 0 | T54: =1000*T6*T$49/1000000 -> 0 | U54: =1000*U6*U$49/1000000 -> 1.2004226e-06 | V54: =1000*V6*V$49/1000000 -> 0 | W54: =1000*W6*W$49/1000000 -> 0 | X54: =1000*X6*X$49/1000000 -> 1.1626982e-06 | Z54: =1000*Z6*Z$49/1000000 -> 0.0011419089 | AA54: =1000*AA6*AA$49/1000000 -> 5.8147206e-07 | AB54: =1000*AB6*AB$49/1000000 -> 0.00013929836 | AC54: =1000*AC6*AC$49/1000000 -> 7.82131e-05 | AD54: =1000*AD6*AD$49/1000000 -> 0.00020029857 | AE54: =1000*AE6*AE$49/1000000 -> 0.00048661788 | AF54: =1000*AF6*AF$49/1000000 -> 0.00012599932
A55: 2021 | B55: =1000*B7*B$49/1000000 -> 0.001544296 | C55: =1000*C7*C$49/1000000 -> 0.0012284861 | D55: =1000*D7*D$49/1000000 -> 0.054705659 | E55: =1000*E7*E$49/1000000 -> 7.804017e-05 | F55: =1000*F7*F$49/1000000 -> 0.033426646 | G55: =1000*G7*G$49/1000000 -> 0.00025382852 | H55: =1000*H7*H$49/1000000 -> 0.004999912 | I55: =1000*I7*I$49/1000000 -> 0 | ... P55: =1000*P7*P$49/1000000 -> 1.7793328e-06 | R55: =1000*R7*R$49/1000000 -> 2.9283711e-05 | S55: =1000*S7*S$49/1000000 -> 0 | T55: =1000*T7*T$49/1000000 -> 0 | U55: =1000*U7*U$49/1000000 -> 1.9873651e-06 | V55: =1000*V7*V$49/1000000 -> 0 | W55: =1000*W7*W$49/1000000 -> 0 | X55: =1000*X7*X$49/1000000 -> 1.7136984e-06 | Z55: =1000*Z7*Z$49/1000000 -> 0.0018904926 | AA55: =1000*AA7*AA$49/1000000 -> 9.6265875e-07 | AB55: =1000*AB7*AB$49/1000000 -> 0.00023061604 | AC55: =1000*AC7*AC$49/1000000 -> 0.00012948606 | AD55: =1000*AD7*AD$49/1000000 -> 0.00033160522 | AE55: =1000*AE7*AE$49/1000000 -> 0.00080562248 | AF55: =1000*AF7*AF$49/1000000 -> 0.00018571013
A56: 2021.25 | B56: =1000*B8*B$49/1000000 -> 0.0032509734 | C56: =1000*C8*C$49/1000000 -> 0.0025861464 | D56: =1000*D8*D$49/1000000 -> 0.11656388 | E56: =1000*E8*E$49/1000000 -> 0.0001642862 | F56: =1000*F8*F$49/1000000 -> 0.070001763 | G56: =1000*G8*G$49/1000000 -> 0.00053824987 | H56: =1000*H8*H$49/1000000 -> 0.011270035 | I56: =1000*I8*I$49/1000000 -> 0 | ... P56: =1000*P8*P$49/1000000 -> 4.0052474e-06 | R56: =1000*R8*R$49/1000000 -> 6.1646578e-05 | S56: =1000*S8*S$49/1000000 -> 0 | T56: =1000*T8*T$49/1000000 -> 0 | U56: =1000*U8*U$49/1000000 -> 4.1837e-06 | V56: =1000*V8*V$49/1000000 -> 0 | W56: =1000*W8*W$49/1000000 -> 0 | X56: =1000*X8*X$49/1000000 -> 3.8408605e-06 | Z56: =1000*Z8*Z$49/1000000 -> 0.0039797689 | AA56: =1000*AA8*AA$49/1000000 -> 2.0265402e-06 | AB56: =1000*AB8*AB$49/1000000 -> 0.00049138425 | AC56: =1000*AC8*AC$49/1000000 -> 0.00027258746 | AD56: =1000*AD8*AD$49/1000000 -> 0.00069444447 | AE56: =1000*AE8*AE$49/1000000 -> 0.0017083431 | AF56: =1000*AF8*AF$49/1000000 -> 0.00041712865
A57: 2021.5 | B57: =1000*B9*B$49/1000000 -> 0.0068049562 | C57: =1000*C9*C$49/1000000 -> 0.0054133365 | D57: =1000*D9*D$49/1000000 -> 0.24828778 | E57: =1000*E9*E$49/1000000 -> 0.00034388481 | F57: =1000*F9*F$49/1000000 -> 0.14540438 | G57: =1000*G9*G$49/1000000 -> 0.0011386406 | H57: =1000*H9*H$49/1000000 -> 0.026471062 | I57: =1000*I9*I$49/1000000 -> 0 | ... P57: =1000*P9*P$49/1000000 -> 9.3887355e-06 | R57: =1000*R9*R$49/1000000 -> 0.00012903897 | S57: =1000*S9*S$49/1000000 -> 0 | T57: =1000*T9*T$49/1000000 -> 0 | U57: =1000*U9*U$49/1000000 -> 8.7573449e-06 | V57: =1000*V9*V$49/1000000 -> 0 | W57: =1000*W9*W$49/1000000 -> 0 | X57: =1000*X9*X$49/1000000 -> 8.9459492e-06 | Z57: =1000*Z9*Z$49/1000000 -> 0.0083304751 | AA57: =1000*AA9*AA$49/1000000 -> 4.2419657e-06 | AB57: =1000*AB9*AB$49/1000000 -> 0.0010466768 | AC57: =1000*AC9*AC$49/1000000 -> 0.00057058165 | AD57: =1000*AD9*AD$49/1000000 -> 0.0014424676 | AE57: =1000*AE9*AE$49/1000000 -> 0.0036139142 | AF57: =1000*AF9*AF$49/1000000 -> 0.00097468316
A58: 2021.75 | B58: =1000*B10*B$49/1000000 -> 0.0097385376 | C58: =1000*C10*C$49/1000000 -> 0.0077469979 | D58: =1000*D10*D$49/1000000 -> 0.3594151 | E58: =1000*E10*E$49/1000000 -> 0.00049213177 | F58: =1000*F10*F$49/1000000 -> 0.20701709 | G58: =1000*G10*G$49/1000000 -> 0.0016409074 | H58: =1000*H10*H$49/1000000 -> 0.037359238 | I58: =1000*I10*I$49/1000000 -> 0 | ... P58: =1000*P10*P$49/1000000 -> 1.3235758e-05 | R58: =1000*R10*R$49/1000000 -> 0.000184667 | S58: =1000*S10*S$49/1000000 -> 0 | T58: =1000*T10*T$49/1000000 -> 0 | U58: =1000*U10*U$49/1000000 -> 1.2532591e-05 | V58: =1000*V10*V$49/1000000 -> 0 | W58: =1000*W10*W$49/1000000 -> 0 | X58: =1000*X10*X$49/1000000 -> 1.2566242e-05 | Z58: =1000*Z10*Z$49/1000000 -> 0.0119217 | AA58: =1000*AA10*AA$49/1000000 -> 6.0706552e-06 | AB58: =1000*AB10*AB$49/1000000 -> 0.0015151428 | AC58: =1000*AC10*AC$49/1000000 -> 0.00081655644 | AD58: =1000*AD10*AD$49/1000000 -> 0.0020536893 | AE58: =1000*AE10*AE$49/1000000 -> 0.005208051 | AF58: =1000*AF10*AF$49/1000000 -> 0.0013716045
A59: 2022 | B59: =1000*B11*B$49/1000000 -> 0.016141343 | C59: =1000*C11*C$49/1000000 -> 0.012840424 | D59: =1000*D11*D$49/1000000 -> 0.60718395 | E59: =1000*E11*E$49/1000000 -> 0.00081569413 | F59: =1000*F11*F$49/1000000 -> 0.34012593 | G59: =1000*G11*G$49/1000000 -> 0.0027517089 | H59: =1000*H11*H$49/1000000 -> 0.064778252 | I59: =1000*I11*I$49/1000000 -> 0 | ... P59: =1000*P11*P$49/1000000 -> 2.2901155e-05 | R59: =1000*R11*R$49/1000000 -> 0.0003060802 | S59: =1000*S11*S$49/1000000 -> 0 | T59: =1000*T11*T$49/1000000 -> 0 | U59: =1000*U11*U$49/1000000 -> 2.0772406e-05 | V59: =1000*V11*V$49/1000000 -> 0 | W59: =1000*W11*W$49/1000000 -> 0 | X59: =1000*X11*X$49/1000000 -> 2.1593369e-05 | Z59: =1000*Z11*Z$49/1000000 -> 0.019759872 | AA59: =1000*AA11*AA$49/1000000 -> 1.0061935e-05 | AB59: =1000*AB11*AB$49/1000000 -> 0.002559632 | AC59: =1000*AC11*AC$49/1000000 -> 0.0013534186 | AD59: =1000*AD11*AD$49/1000000 -> 0.0033741803 | AE59: =1000*AE11*AE$49/1000000 -> 0.0087336071 | AF59: =1000*AF11*AF$49/1000000 -> 0.0023651268
A60: 2022.25 | B60: =1000*B12*B$49/1000000 -> 0.024451671 | C60: =1000*C12*C$49/1000000 -> 0.019451282 | D60: =1000*D12*D$49/1000000 -> 0.93553478 | E60: =1000*E12*E$49/1000000 -> 0.0012356521 | F60: =1000*F12*F$49/1000000 -> 0.51112035 | G60: =1000*G12*G$49/1000000 -> 0.0042123006 | H60: =1000*H12*H$49/1000000 -> 0.10141195 | I60: =1000*I12*I$49/1000000 -> 0 | ... P60: =1000*P12*P$49/1000000 -> 3.5785613e-05 | R60: =1000*R12*R$49/1000000 -> 0.00046366477 | S60: =1000*S12*S$49/1000000 -> 0 | T60: =1000*T12*T$49/1000000 -> 0 | U60: =1000*U12*U$49/1000000 -> 3.1467023e-05 | V60: =1000*V12*V$49/1000000 -> 0 | W60: =1000*W12*W$49/1000000 -> 0 | X60: =1000*X12*X$49/1000000 -> 3.3537038e-05 | Z60: =1000*Z12*Z$49/1000000 -> 0.029933188 | AA60: =1000*AA12*AA$49/1000000 -> 1.5242295e-05 | AB60: =1000*AB12*AB$49/1000000 -> 0.003943821 | AC60: =1000*AC12*AC$49/1000000 -> 0.0020502225 | AD60: =1000*AD12*AD$49/1000000 -> 0.0050705109 | AE60: =1000*AE12*AE$49/1000000 -> 0.013369357 | AF60: =1000*AF12*AF$49/1000000 -> 0.0036846695
