Workbook

Sheet final data summary
A1: cc | C1: PAG | D1: Sur | E1: TARC | F1: Polymer | G1: ITC | H1: PBO | I1: Total | J1: Error | M1: share cc | N1: Gas | O1: Solid | P1: Solvent | Q1: Water | S1: {=INDEX($M$1:$Q$14, COLUMN(A1), ROW(A1))} -> share cc | T1: {=INDEX($M$1:$Q$14, COLUMN(B1), ROW(B1))} -> 2025 Basic | U1: {=INDEX($M$1:$Q$14, COLUMN(C1), ROW(C1))} -> 1 | V1: {=INDEX($M$1:$Q$14, COLUMN(D1), ROW(D1))} -> 2 | W1: {=INDEX($M$1:$Q$14, COLUMN(E1), ROW(E1))} -> 3 | X1: {=INDEX($M$1:$Q$14, COLUMN(F1), ROW(F1))} -> 4 | Y1: {=INDEX($M$1:$Q$14, COLUMN(G1), ROW(G1))} -> 5 | Z1: {=INDEX($M$1:$Q$14, COLUMN(H1), ROW(H1))} -> 0 | ... AF1: {=INDEX($M$1:$Q$14, COLUMN(N1), ROW(N1))} -> 5
B2: 2025 Basic | C2: =baseline!C5 -> 4291644.3 | D2: =baseline!C6 -> 253761.86 | E2: =baseline!C7 -> 13251754 | F2: =baseline!C8 -> 288306.42 | G2: =baseline!C9 -> 6923658.6 | H2: =baseline!C10 -> 2567312.2 | I2: =baseline!C11 -> 27576438 | J2: 0 | M2: 2025 Basic | N2: =baseline!M5 -> 0.00017823069 | O2: =baseline!M6 -> 0.0020559817 | P2: =baseline!M7 -> 0.1677993 | Q2: =baseline!M8 -> 0.82996649 | S2: {=INDEX($M$1:$Q$14, COLUMN(A2), ROW(A2))} -> Gas | T2: {=INDEX($M$1:$Q$14, COLUMN(B2), ROW(B2))} -> 0.00017823069 | U2: {=INDEX($M$1:$Q$14, COLUMN(C2), ROW(C2))} -> 0.002545277 | V2: {=INDEX($M$1:$Q$14, COLUMN(D2), ROW(D2))} -> 0.0028614051 | W2: {=INDEX($M$1:$Q$14, COLUMN(E2), ROW(E2))} -> 0.0032549332 | X2: {=INDEX($M$1:$Q$14, COLUMN(F2), ROW(F2))} -> 0.0023671226 | Y2: {=INDEX($M$1:$Q$14, COLUMN(G2), ROW(G2))} -> 0.001863806 | Z2: {=INDEX($M$1:$Q$14, COLUMN(H2), ROW(H2))} -> 0 | ... AF2: {=INDEX($M$1:$Q$14, COLUMN(N2), ROW(N2))} -> 0.0018643197
B3: 1 | C3: ='1-incineration improvement'!B69 -> 4250836.5 | D3: ='1-incineration improvement'!C69 -> 227953.69 | E3: ='1-incineration improvement'!D69 -> 11947982 | F3: ='1-incineration improvement'!E69 -> 286093.81 | G3: ='1-incineration improvement'!F69 -> 6276589 | H3: ='1-incineration improvement'!G69 -> 2554061.2 | I3: ='1-incineration improvement'!H69 -> 25543516 | J3: ='1-incineration improvement'!I69 -> 251386 | M3: 1 | N3: ='1-incineration improvement'!B73 -> 0.002545277 | O3: ='1-incineration improvement'!C73 -> 0.0030171898 | P3: ='1-incineration improvement'!D73 -> 0.30408161 | Q3: ='1-incineration improvement'!E73 -> 0.69035592 | S3: {=INDEX($M$1:$Q$14, COLUMN(A3), ROW(A3))} -> Solid | T3: {=INDEX($M$1:$Q$14, COLUMN(B3), ROW(B3))} -> 0.0020559817 | U3: {=INDEX($M$1:$Q$14, COLUMN(C3), ROW(C3))} -> 0.0030171898 | V3: {=INDEX($M$1:$Q$14, COLUMN(D3), ROW(D3))} -> 0.0033919522 | W3: {=INDEX($M$1:$Q$14, COLUMN(E3), ROW(E3))} -> 0.0038584337 | X3: {=INDEX($M$1:$Q$14, COLUMN(F3), ROW(F3))} -> 0.0028058993 | Y3: {=INDEX($M$1:$Q$14, COLUMN(G3), ROW(G3))} -> 0.0026315744 | Z3: {=INDEX($M$1:$Q$14, COLUMN(H3), ROW(H3))} -> 0 | ... AF3: {=INDEX($M$1:$Q$14, COLUMN(N3), ROW(N3))} -> 0.0029001459
B4: 2 | C4: ='2-better separation'!B69 -> 4205472.4 | D4: ='2-better separation'!C69 -> 192430.31 | E4: ='2-better separation'!D69 -> 10154093 | F4: ='2-better separation'!E69 -> 283788.62 | G4: ='2-better separation'!F69 -> 5387694.8 | H4: ='2-better separation'!G69 -> 2542757.4 | I4: ='2-better separation'!H69 -> 22766236 | J4: ='2-better separation'!I69 -> 1089843.2 | M4: 2 | N4: ='2-better separation'!B73 -> 0.0028614051 | O4: ='2-better separation'!C73 -> 0.0033919522 | P4: ='2-better separation'!D73 -> 0.34185258 | Q4: ='2-better separation'!E73 -> 0.65189407 | S4: {=INDEX($M$1:$Q$14, COLUMN(A4), ROW(A4))} -> Solvent | T4: {=INDEX($M$1:$Q$14, COLUMN(B4), ROW(B4))} -> 0.1677993 | U4: {=INDEX($M$1:$Q$14, COLUMN(C4), ROW(C4))} -> 0.30408161 | V4: {=INDEX($M$1:$Q$14, COLUMN(D4), ROW(D4))} -> 0.34185258 | W4: {=INDEX($M$1:$Q$14, COLUMN(E4), ROW(E4))} -> 0.38886547 | X4: {=INDEX($M$1:$Q$14, COLUMN(F4), ROW(F4))} -> 0.28278109 | Y4: {=INDEX($M$1:$Q$14, COLUMN(G4), ROW(G4))} -> 0.2561999 | Z4: {=INDEX($M$1:$Q$14, COLUMN(H4), ROW(H4))} -> 0 | ... AF4: {=INDEX($M$1:$Q$14, COLUMN(N4), ROW(N4))} -> 0.28786187
B5: 3 | C5: ='3-Source management'!B69 -> 4162632.1 | D5: ='3-Source management'!C69 -> 156819.38 | E5: ='3-Source management'!D69 -> 8356341.2 | F5: ='3-Source management'!E69 -> 281658.32 | G5: ='3-Source management'!F69 -> 4496888.7 | H5: ='3-Source management'!G69 -> 2532972.5 | I5: ='3-Source management'!H69 -> 19987312 | J5: ='3-Source management'!I69 -> 417897.13 | M5: 3 | N5: ='3-Source management'!B73 -> 0.0032549332 | O5: ='3-Source management'!C73 -> 0.0038584337 | P5: ='3-Source management'!D73 -> 0.38886547 | Q5: ='3-Source management'!E73 -> 0.60402116 | S5: {=INDEX($M$1:$Q$14, COLUMN(A5), ROW(A5))} -> Water | T5: {=INDEX($M$1:$Q$14, COLUMN(B5), ROW(B5))} -> 0.82996649 | U5: {=INDEX($M$1:$Q$14, COLUMN(C5), ROW(C5))} -> 0.69035592 | V5: {=INDEX($M$1:$Q$14, COLUMN(D5), ROW(D5))} -> 0.65189407 | W5: {=INDEX($M$1:$Q$14, COLUMN(E5), ROW(E5))} -> 0.60402116 | X5: {=INDEX($M$1:$Q$14, COLUMN(F5), ROW(F5))} -> 0.71204589 | Y5: {=INDEX($M$1:$Q$14, COLUMN(G5), ROW(G5))} -> 0.73930472 | Z5: {=INDEX($M$1:$Q$14, COLUMN(H5), ROW(H5))} -> 0 | ... AF5: {=INDEX($M$1:$Q$14, COLUMN(N5), ROW(N5))} -> 0.70737367
B6: 4 | C6: ='4-Cascade'!B70 -> 4127118.3 | D6: ='4-Cascade'!C70 -> 243399.26 | E6: ='4-Cascade'!D70 -> 12713183 | F6: ='4-Cascade'!E70 -> 277268.14 | G6: ='4-Cascade'!F70 -> 6641945.6 | H6: ='4-Cascade'!G70 -> 2468712.7 | I6: ='4-Cascade'!H70 -> 26471627 | J6: ='4-Cascade'!I70 -> 172943.83 | M6: 4 | N6: ='4-Cascade'!B77 -> 0.0023671226 | O6: ='4-Cascade'!C77 -> 0.0028058993 | P6: ='4-Cascade'!D77 -> 0.28278109 | Q6: ='4-Cascade'!E77 -> 0.71204589
B7: 5 | C7: ='5-alternativess'!B75 -> 1070400.5 | D7: ='5-alternativess'!C75 -> 252517.58 | E7: ='5-alternativess'!D75 -> 13188280 | F7: ='5-alternativess'!E75 -> 287668.53 | G7: ='5-alternativess'!F75 -> 6891253.8 | H7: ='5-alternativess'!G75 -> 2561816.5 | I7: ='5-alternativess'!H75 -> 24251937 | J7: ='5-alternativess'!I75 -> 1068601.8 | M7: 5 | N7: ='5-alternativess'!B82 -> 0.001863806 | O7: ='5-alternativess'!C82 -> 0.0026315744 | P7: ='5-alternativess'!D82 -> 0.2561999 | Q7: ='5-alternativess'!E82 -> 0.73930472
B9: 2030 Basic | C9: =baseline!C13 -> 30662087 | D9: =baseline!C14 -> 1697236.7 | E9: =baseline!C15 -> 91286001 | F9: =baseline!C16 -> 2062446.1 | G9: =baseline!C17 -> 47423398 | H9: =baseline!C18 -> 23203041 | I9: =SUM(C9:H9) -> 1.9633421e+08 | M9: 2030 Basic | N9: =baseline!M11 -> 0.00018205462 | O9: =baseline!M12 -> 0.0024010295 | P9: =baseline!M13 -> 0.20477121 | Q9: =baseline!M14 -> 0.79264571
B10: 1 | C10: ='1-incineration improvement'!J69 -> 30455741 | D10: ='1-incineration improvement'!K69 -> 1515866.1 | E10: ='1-incineration improvement'!L69 -> 81879331 | F10: ='1-incineration improvement'!M69 -> 2052407.8 | G10: ='1-incineration improvement'!N69 -> 42807326 | H10: ='1-incineration improvement'!O69 -> 23149460 | I10: ='1-incineration improvement'!P69 -> 1.8186013e+08 | J10: ='1-incineration improvement'!Q69 -> 1804661.3 | M10: 1 | N10: ='1-incineration improvement'!J73 -> 0.0025262533 | O10: ='1-incineration improvement'!K73 -> 0.0032599702 | P10: ='1-incineration improvement'!L73 -> 0.33418916 | Q10: ='1-incineration improvement'!M73 -> 0.66002462
B11: 2 | C11: ='2-better separation'!J69 -> 30151935 | D11: ='2-better separation'!K69 -> 1302732.3 | E11: ='2-better separation'!L69 -> 70819581 | F11: ='2-better separation'!M69 -> 2036409.9 | G11: ='2-better separation'!N69 -> 37373776 | H11: ='2-better separation'!O69 -> 23038113 | I11: ='2-better separation'!P69 -> 1.6472255e+08 | J11: ='2-better separation'!Q69 -> 7109292.4 | M11: 2 | N11: ='2-better separation'!J73 -> 0.0027904641 | O11: ='2-better separation'!K73 -> 0.0036008958 | P11: ='2-better separation'!L73 -> 0.36913842 | Q11: ='2-better separation'!M73 -> 0.62447022
B12: 3 | C12: ='3-Source management'!J69 -> 29917293 | D12: ='3-Source management'!K69 -> 1073642.6 | E12: ='3-Source management'!L69 -> 58942676 | F12: ='3-Source management'!M69 -> 2025511.5 | G12: ='3-Source management'!N69 -> 31546960 | H12: ='3-Source management'!O69 -> 22992062 | I12: ='3-Source management'!P69 -> 1.4649814e+08 | J12: ='3-Source management'!Q69 -> 2945191.9 | M12: 3 | N12: ='3-Source management'!J73 -> 0.0031388306 | O12: ='3-Source management'!K73 -> 0.0040504904 | P12: ='3-Source management'!L73 -> 0.41522774 | Q12: ='3-Source management'!M73 -> 0.57758294
B13: 4 | C13: ='4-Cascade'!J70 -> 27371487 | D13: ='4-Cascade'!K70 -> 1457701.9 | E13: ='4-Cascade'!L70 -> 78516609 | F13: ='4-Cascade'!M70 -> 1842405.3 | G13: ='4-Cascade'!N70 -> 40883107 | H13: ='4-Cascade'!O70 -> 20745719 | I13: ='4-Cascade'!P70 -> 1.7081703e+08 | J13: ='4-Cascade'!Q70 -> 7089010.6 | M13: 4 | N13: ='4-Cascade'!J77 -> 0.0024056432 | O13: ='4-Cascade'!K77 -> 0.0031042202 | P13: ='4-Cascade'!L77 -> 0.31822269 | Q13: ='4-Cascade'!M77 -> 0.67626745
B14: 5 | C14: ='5-alternativess'!J75 -> 7652940.7 | D14: ='5-alternativess'!K75 -> 1629204.8 | E14: ='5-alternativess'!L75 -> 87757470 | F14: ='5-alternativess'!M75 -> 2059225.4 | G14: ='5-alternativess'!N75 -> 45693121 | H14: ='5-alternativess'!O75 -> 23189671 | I14: ='5-alternativess'!P75 -> 1.6798163e+08 | J14: ='5-alternativess'!Q75 -> 7752767.3 | M14: 5 | N14: ='5-alternativess'!J82 -> 0.0018643197 | O14: ='5-alternativess'!K82 -> 0.0029001459 | P14: ='5-alternativess'!L82 -> 0.28786187 | Q14: ='5-alternativess'!M82 -> 0.70737367
B17: 2025 Basic | C17: =C2/$I$2 -> 0.15562722 | D17: =D2/$I$2 -> 0.0092021262 | E17: =E2/$I$2 -> 0.48054627 | F17: =F2/$I$2 -> 0.01045481 | G17: =G2/$I$2 -> 0.25107154 | H17: =H2/$I$2 -> 0.093098036 | I17: =I2/$I$2 -> 1 | J17: =J2/$I$2 -> 0
B18: 2025 S1 | C18: =C3/$I$2 -> 0.15414741 | D18: =D3/$I$2 -> 0.0082662488 | E18: =E3/$I$2 -> 0.43326778 | F18: =F3/$I$2 -> 0.010374575 | G18: =G3/$I$2 -> 0.22760696 | H18: =H3/$I$2 -> 0.092617518 | I18: =I3/$I$2 -> 0.92628049 | J18: =J3/$I$2 -> 0.0091159707
B19: 2025 S2 | C19: =C4/$I$2 -> 0.15250238 | D19: =D4/$I$2 -> 0.0069780699 | E19: =E4/$I$2 -> 0.36821626 | F19: =F4/$I$2 -> 0.010290982 | G19: =G4/$I$2 -> 0.19537312 | H19: =H4/$I$2 -> 0.092207611 | I19: =I4/$I$2 -> 0.82556842 | J19: =J4/$I$2 -> 0.039520813
B20: 2025 S3 | C20: =C5/$I$2 -> 0.15094887 | D20: =D5/$I$2 -> 0.0056867166 | E20: =E5/$I$2 -> 0.30302468 | F20: =F5/$I$2 -> 0.010213731 | G20: =G5/$I$2 -> 0.16306996 | H20: =H5/$I$2 -> 0.09185278 | I20: =I5/$I$2 -> 0.72479674 | J20: =J5/$I$2 -> 0.015154137
B21: 2025 S4 | C21: =C6/$I$2 -> 0.14966104 | D21: =D6/$I$2 -> 0.0088263488 | E21: =E6/$I$2 -> 0.46101616 | F21: =F6/$I$2 -> 0.010054531 | G21: =G6/$I$2 -> 0.24085582 | H21: =H6/$I$2 -> 0.089522537 | I21: =I6/$I$2 -> 0.95993643 | J21: =J6/$I$2 -> 0.0062714347
B22: 2025 S5 | C22: =C7/$I$2 -> 0.038815765 | D22: =D7/$I$2 -> 0.009157005 | E22: =E7/$I$2 -> 0.47824452 | F22: =F7/$I$2 -> 0.010431678 | G22: =G7/$I$2 -> 0.24989645 | H22: =H7/$I$2 -> 0.092898748 | I22: =I7/$I$2 -> 0.87944416 | J22: =J7/$I$2 -> 0.038750539
B24: 2030 Basic | C24: =C9/$I$9 -> 0.15617292 | D24: =D9/$I$9 -> 0.0086446307 | E24: =E9/$I$9 -> 0.46495209 | F24: =F9/$I$9 -> 0.010504772 | G24: =G9/$I$9 -> 0.24154424 | H24: =H9/$I$9 -> 0.11818134 | I24: =I9/$I$9 -> 1 | J24: =J9/$I$9 -> 0
B25: 2030 S1 | C25: =C10/$I$9 -> 0.15512193 | D25: =D10/$I$9 -> 0.0077208457 | E25: =E10/$I$9 -> 0.41704057 | F25: =F10/$I$9 -> 0.010453643 | G25: =G10/$I$9 -> 0.21803295 | H25: =H10/$I$9 -> 0.11790844 | I25: =I10/$I$9 -> 0.92627837 | J25: =J10/$I$9 -> 0.009191782
B26: 2030 S2 | C26: =C11/$I$9 -> 0.15357453 | D26: =D11/$I$9 -> 0.0066352791 | E26: =E11/$I$9 -> 0.36070933 | F26: =F11/$I$9 -> 0.01037216 | G26: =G11/$I$9 -> 0.19035794 | H26: =H11/$I$9 -> 0.11734131 | I26: =I11/$I$9 -> 0.83899055 | J26: =J11/$I$9 -> 0.036210156
B27: 2030 S3 | C27: =C12/$I$9 -> 0.15237942 | D27: =D12/$I$9 -> 0.0054684441 | E27: =E12/$I$9 -> 0.30021602 | F27: =F12/$I$9 -> 0.010316651 | G27: =G12/$I$9 -> 0.16067989 | H27: =H12/$I$9 -> 0.11710675 | I27: =I12/$I$9 -> 0.74616718 | J27: =J12/$I$9 -> 0.015000911
B28: 2030 S4 | C28: =C13/$I$9 -> 0.13941272 | D28: =D13/$I$9 -> 0.0074245948 | E28: =E13/$I$9 -> 0.39991303 | F28: =F13/$I$9 -> 0.0093840257 | G28: =G13/$I$9 -> 0.20823221 | H28: =H13/$I$9 -> 0.10566533 | I28: =I13/$I$9 -> 0.87003192 | J28: =J13/$I$9 -> 0.036106854
B29: 2030 S5 | C29: =C14/$I$9 -> 0.03897915 | D29: =D14/$I$9 -> 0.0082981199 | E29: =E14/$I$9 -> 0.44698002 | F29: =F14/$I$9 -> 0.010488368 | G29: =G14/$I$9 -> 0.23273133 | H29: =H14/$I$9 -> 0.11811325 | I29: =I14/$I$9 -> 0.85559023 | J29: =J14/$I$9 -> 0.039487603
A32: HTC | C32: PAG | D32: Sur | E32: TARC | F32: Polymer | G32: ITC | H32: PBO | J32: Error | M32: share cc | N32: Gas | O32: Solid | P32: Solvent | Q32: Water | S32: {=INDEX($M$32:$Q$45, COLUMN(A1), ROW(A1))} -> share cc | T32: {=INDEX($M$32:$Q$45, COLUMN(B1), ROW(B1))} -> 2025 Basic | U32: {=INDEX($M$32:$Q$45, COLUMN(C1), ROW(C1))} -> 1 | V32: {=INDEX($M$32:$Q$45, COLUMN(D1), ROW(D1))} -> 2 | W32: {=INDEX($M$32:$Q$45, COLUMN(E1), ROW(E1))} -> 3 | X32: {=INDEX($M$32:$Q$45, COLUMN(F1), ROW(F1))} -> 4 | Y32: {=INDEX($M$32:$Q$45, COLUMN(G1), ROW(G1))} -> 5 | Z32: {=INDEX($M$32:$Q$45, COLUMN(H1), ROW(H1))} -> 0 | ... AF32: {=INDEX($M$32:$Q$45, COLUMN(N1), ROW(N1))} -> 5
B33: 2025 Basic | C33: =baseline!D5 -> 0.24826856 | D33: =baseline!D6 -> 0.028821129 | E33: =baseline!D7 -> 1.4784422 | F33: =baseline!D8 -> 0.016359843 | G33: =baseline!D9 -> 0.75131606 | H33: =baseline!D10 -> 0.14077843 | I33: =SUM(C33:H33) -> 2.6639862 | M33: 2025 Basic | N33: =baseline!Q5 -> 0.00014056137 | O33: =baseline!Q6 -> 0.001621412 | P33: =baseline!Q7 -> 0.085361998 | Q33: =baseline!Q8 -> 0.91287603 | S33: {=INDEX($M$32:$Q$45, COLUMN(A2), ROW(A2))} -> Gas | T33: {=INDEX($M$32:$Q$45, COLUMN(B2), ROW(B2))} -> 0.00014056137 | U33: {=INDEX($M$32:$Q$45, COLUMN(C2), ROW(C2))} -> 0.0020939844 | V33: {=INDEX($M$32:$Q$45, COLUMN(D2), ROW(D2))} -> 0.0026357137 | W33: {=INDEX($M$32:$Q$45, COLUMN(E2), ROW(E2))} -> 0.0032153376 | X33: {=INDEX($M$32:$Q$45, COLUMN(F2), ROW(F2))} -> 0.0020049167 | Y33: {=INDEX($M$32:$Q$45, COLUMN(G2), ROW(G2))} -> 0.001558461 | Z33: {=INDEX($M$32:$Q$45, COLUMN(H2), ROW(H2))} -> 0 | ... AF33: {=INDEX($M$32:$Q$45, COLUMN(N2), ROW(N2))} -> 0.001630566
B34: 1 | C34: ='1-incineration improvement'!B70 -> 0.24579662 | D34: ='1-incineration improvement'!C70 -> 0.027209108 | E34: ='1-incineration improvement'!D70 -> 1.3970181 | F34: ='1-incineration improvement'!E70 -> 0.016226912 | G34: ='1-incineration improvement'!F70 -> 0.71091019 | H34: ='1-incineration improvement'!G70 -> 0.14000161 | I34: ='1-incineration improvement'!H70 -> 2.5371625 | J34: ='1-incineration improvement'!I70 -> 0.014263075 | M34: 1 | N34: ='1-incineration improvement'!B74 -> 0.0020939844 | O34: ='1-incineration improvement'!C74 -> 0.0024821913 | P34: ='1-incineration improvement'!D74 -> 0.16137319 | Q34: ='1-incineration improvement'!E74 -> 0.83405063 | S34: {=INDEX($M$32:$Q$45, COLUMN(A3), ROW(A3))} -> Solid | T34: {=INDEX($M$32:$Q$45, COLUMN(B3), ROW(B3))} -> 0.001621412 | U34: {=INDEX($M$32:$Q$45, COLUMN(C3), ROW(C3))} -> 0.0024821913 | V34: {=INDEX($M$32:$Q$45, COLUMN(D3), ROW(D3))} -> 0.0031243728 | W34: {=INDEX($M$32:$Q$45, COLUMN(E3), ROW(E3))} -> 0.0038114459 | X34: {=INDEX($M$32:$Q$45, COLUMN(F3), ROW(F3))} -> 0.0023765223 | Y34: {=INDEX($M$32:$Q$45, COLUMN(G3), ROW(G3))} -> 0.0021932755 | Z34: {=INDEX($M$32:$Q$45, COLUMN(H3), ROW(H3))} -> 0 | ... AF34: {=INDEX($M$32:$Q$45, COLUMN(N3), ROW(N3))} -> 0.00253354
B35: 2 | C35: ='2-better separation'!B70 -> 0.23752688 | D35: ='2-better separation'!C70 -> 0.020661408 | E35: ='2-better separation'!D70 -> 1.066388 | F35: ='2-better separation'!E70 -> 0.015808307 | G35: ='2-better separation'!F70 -> 0.54707741 | H35: ='2-better separation'!G70 -> 0.13796674 | I35: ='2-better separation'!H70 -> 2.0254287 | J35: ='2-better separation'!I70 -> 0.14442489 | M35: 2 | N35: ='2-better separation'!B74 -> 0.0026357137 | O35: ='2-better separation'!C74 -> 0.0031243728 | P35: ='2-better separation'!D74 -> 0.2031234 | Q35: ='2-better separation'!E74 -> 0.79111652 | S35: {=INDEX($M$32:$Q$45, COLUMN(A4), ROW(A4))} -> Solvent | T35: {=INDEX($M$32:$Q$45, COLUMN(B4), ROW(B4))} -> 0.085361998 | U35: {=INDEX($M$32:$Q$45, COLUMN(C4), ROW(C4))} -> 0.16137319 | V35: {=INDEX($M$32:$Q$45, COLUMN(D4), ROW(D4))} -> 0.2031234 | W35: {=INDEX($M$32:$Q$45, COLUMN(E4), ROW(E4))} -> 0.24779148 | X35: {=INDEX($M$32:$Q$45, COLUMN(F4), ROW(F4))} -> 0.15450143 | Y35: {=INDEX($M$32:$Q$45, COLUMN(G4), ROW(G4))} -> 0.13782361 | Z35: {=INDEX($M$32:$Q$45, COLUMN(H4), ROW(H4))} -> 0 | ... AF35: {=INDEX($M$32:$Q$45, COLUMN(N4), ROW(N4))} -> 0.15869439
B36: 3 | C36: ='3-Source management'!B70 -> 0.23166305 | D36: ='3-Source management'!C70 -> 0.015914618 | E36: ='3-Source management'!D70 -> 0.82672859 | F36: ='3-Source management'!E70 -> 0.015513838 | G36: ='3-Source management'!F70 -> 0.42831779 | H36: ='3-Source management'!G70 -> 0.13656866 | I36: ='3-Source management'!H70 -> 1.6547065 | J36: ='3-Source management'!I70 -> 0.05624156 | M36: 3 | N36: ='3-Source management'!B74 -> 0.0032153376 | O36: ='3-Source management'!C74 -> 0.0038114459 | P36: ='3-Source management'!D74 -> 0.24779148 | Q36: ='3-Source management'!E74 -> 0.74518174 | S36: {=INDEX($M$32:$Q$45, COLUMN(A5), ROW(A5))} -> Water | T36: {=INDEX($M$32:$Q$45, COLUMN(B5), ROW(B5))} -> 0.91287603 | U36: {=INDEX($M$32:$Q$45, COLUMN(C5), ROW(C5))} -> 0.83405063 | V36: {=INDEX($M$32:$Q$45, COLUMN(D5), ROW(D5))} -> 0.79111652 | W36: {=INDEX($M$32:$Q$45, COLUMN(E5), ROW(E5))} -> 0.74518174 | X36: {=INDEX($M$32:$Q$45, COLUMN(F5), ROW(F5))} -> 0.84111713 | Y36: {=INDEX($M$32:$Q$45, COLUMN(G5), ROW(G5))} -> 0.85842465 | Z36: {=INDEX($M$32:$Q$45, COLUMN(H5), ROW(H5))} -> 0 | ... AF36: {=INDEX($M$32:$Q$45, COLUMN(N5), ROW(N5))} -> 0.83714151
B37: 4 | C37: ='4-Cascade'!B71 -> 0.23867358 | D37: ='4-Cascade'!C71 -> 0.027615654 | E37: ='4-Cascade'!D71 -> 1.416857 | F37: ='4-Cascade'!E71 -> 0.015729645 | G37: ='4-Cascade'!F71 -> 0.71994212 | H37: ='4-Cascade'!G71 -> 0.1353544 | I37: ='4-Cascade'!H71 -> 2.5541724 | J37: ='4-Cascade'!I71 -> 0.016652463 | M37: 4 | N37: ='4-Cascade'!B78 -> 0.0020049167 | O37: ='4-Cascade'!C78 -> 0.0023765223 | P37: ='4-Cascade'!D78 -> 0.15450143 | Q37: ='4-Cascade'!E78 -> 0.84111713
B38: 5 | C38: ='5-alternativess'!B76 -> 0.061899494 | D38: ='5-alternativess'!C76 -> 0.028649177 | E38: ='5-alternativess'!D76 -> 1.4697519 | F38: ='5-alternativess'!E76 -> 0.016319088 | G38: ='5-alternativess'!F76 -> 0.7469372 | H38: ='5-alternativess'!G76 -> 0.14045425 | I38: ='5-alternativess'!H76 -> 2.4640111 | J38: ='5-alternativess'!I76 -> 0.061706464 | M38: 5 | N38: ='5-alternativess'!B83 -> 0.001558461 | O38: ='5-alternativess'!C83 -> 0.0021932755 | P38: ='5-alternativess'!D83 -> 0.13782361 | Q38: ='5-alternativess'!E83 -> 0.85842465
B40: 2030 Basic | C40: =baseline!D13 -> 1.6436131 | D40: =baseline!D14 -> 0.17978428 | E40: =baseline!D15 -> 9.4852979 | F40: =baseline!D16 -> 0.10855634 | G40: =baseline!D17 -> 4.7840823 | H40: =baseline!D18 -> 1.1816198 | I40: =SUM(C40:H40) -> 17.382954 | M40: 2030 Basic | N40: =baseline!Q11 -> 0.00015229379 | O40: =baseline!Q12 -> 0.0020084257 | P40: =baseline!Q13 -> 0.10807117 | Q40: =baseline!Q14 -> 0.88976811
B41: 1 | C41: ='1-incineration improvement'!J70 -> 1.6323173 | D41: ='1-incineration improvement'!K70 -> 0.16994007 | E41: ='1-incineration improvement'!L70 -> 8.974732 | F41: ='1-incineration improvement'!M70 -> 0.10800492 | G41: ='1-incineration improvement'!N70 -> 4.5335198 | H41: ='1-incineration improvement'!O70 -> 1.1786311 | I41: ='1-incineration improvement'!P70 -> 16.597145 | J41: ='1-incineration improvement'!Q70 -> 0.088222717 | M41: 1 | N41: ='1-incineration improvement'!J74 -> 0.0021518587 | O41: ='1-incineration improvement'!K74 -> 0.0027767455 | P41: ='1-incineration improvement'!L74 -> 0.17960017 | Q41: ='1-incineration improvement'!M74 -> 0.81547123
B42: 2 | C42: ='2-better separation'!J70 -> 1.5809886 | D42: ='2-better separation'!K70 -> 0.13052384 | E42: ='2-better separation'!L70 -> 6.9299556 | F42: ='2-better separation'!M70 -> 0.10537904 | G42: ='2-better separation'!N70 -> 3.5293759 | H42: ='2-better separation'!O70 -> 1.16193 | I42: ='2-better separation'!P70 -> 13.438153 | J42: ='2-better separation'!Q70 -> 0.888266 | M42: 2 | N42: ='2-better separation'!J74 -> 0.0026659338 | O42: ='2-better separation'!K74 -> 0.0034400841 | P42: ='2-better separation'!L74 -> 0.22250513 | Q42: ='2-better separation'!M74 -> 0.77138885
B43: 3 | C43: ='3-Source management'!J70 -> 1.5475843 | D43: ='3-Source management'!K70 -> 0.10184787 | E43: ='3-Source management'!L70 -> 5.4428532 | F43: ='3-Source management'!M70 -> 0.10373852 | G43: ='3-Source management'!N70 -> 2.7994117 | H43: ='3-Source management'!O70 -> 1.1529136 | I43: ='3-Source management'!P70 -> 11.148349 | J43: ='3-Source management'!Q70 -> 0.36341932 | M43: 3 | N43: ='3-Source management'!J74 -> 0.0032087626 | O43: ='3-Source management'!K74 -> 0.0041405973 | P43: ='3-Source management'!L74 -> 0.26781403 | Q43: ='3-Source management'!M74 -> 0.72483661
B44: 4 | C44: ='4-Cascade'!J71 -> 1.459311 | D44: ='4-Cascade'!K71 -> 0.15132825 | E44: ='4-Cascade'!L71 -> 7.9920141 | F44: ='4-Cascade'!M71 -> 0.096571247 | G44: ='4-Cascade'!N71 -> 4.037861 | H44: ='4-Cascade'!O71 -> 1.0539795 | I44: ='4-Cascade'!P71 -> 14.791065 | J44: ='4-Cascade'!Q71 -> 0.61377057 | M44: 4 | N44: ='4-Cascade'!J78 -> 0.0021598971 | O44: ='4-Cascade'!K78 -> 0.0027870188 | P44: ='4-Cascade'!L78 -> 0.18026536 | Q44: ='4-Cascade'!M78 -> 0.81478772
B45: 5 | C45: ='5-alternativess'!J76 -> 0.40800969 | D45: ='5-alternativess'!K76 -> 0.16912815 | E45: ='5-alternativess'!L76 -> 8.9323885 | F45: ='5-alternativess'!M76 -> 0.10793386 | G45: ='5-alternativess'!N76 -> 4.5128072 | H45: ='5-alternativess'!O76 -> 1.178121 | I45: ='5-alternativess'!P76 -> 15.308388 | J45: ='5-alternativess'!Q76 -> 0.41738346 | M45: 5 | N45: ='5-alternativess'!J83 -> 0.001630566 | O45: ='5-alternativess'!K83 -> 0.00253354 | P45: ='5-alternativess'!L83 -> 0.15869439 | Q45: ='5-alternativess'!M83 -> 0.83714151
B48: 2025 Basic | C48: =C33/$I$33 -> 0.093194387 | D48: =D33/$I$33 -> 0.010818798 | E48: =E33/$I$33 -> 0.55497366 | F48: =F33/$I$33 -> 0.0061411139 | G48: =G33/$I$33 -> 0.28202701 | H48: =H33/$I$33 -> 0.05284503 | I48: =I33/$I$33 -> 1 | J48: =J33/$I$33 -> 0
B49: 2025 S1 | C49: =C34/$I$33 -> 0.092266478 | D49: =D34/$I$33 -> 0.010213682 | E49: =E34/$I$33 -> 0.52440891 | F49: =F34/$I$33 -> 0.0060912146 | G49: =G34/$I$33 -> 0.26685956 | H49: =H34/$I$33 -> 0.052553429 | I49: =I34/$I$33 -> 0.95239327 | J49: =J34/$I$33 -> 0.0053540351
...

Sheet 1-incineration improvement
A5: 11MJ
A6: ='[1]data summary'!A35 -> yearly | B6: ='[1]data summary'!B35 -> 0 | C6: ='[1]data summary'!C35 -> CC | D6: ='[1]data summary'!D35 -> HTC | E6: ='[1]data summary'!E35 -> CED | G6: ='[2]data summary'!M25 -> 0 | H6: ='[2]data summary'!N25 -> 0 | I6: ='[2]data summary'!O25 -> CC | J6: ='[2]data summary'!P25 -> CC | K6: ='[2]data summary'!Q25 -> 0 | L6: ='[2]data summary'!R25 -> 0 | M6: ='[2]data summary'!S25 -> HTC | N6: ='[2]data summary'!T25 -> HTC | ... S6: ='[2]data summary'!Y25 -> 0
A7: ='[1]data summary'!A36 -> 2025 | B7: ='[1]data summary'!B36 -> PAG | C7: ='[1]data summary'!C36 -> 4251403.3 | D7: ='[1]data summary'!D36 -> 0.24581354 | E7: ='[1]data summary'!E36 -> 30496685 | G7: ='[2]data summary'!M26 -> 2025 | H7: ='[2]data summary'!N26 -> Gas | I7: ='[2]data summary'!O26 -> 0.065086345 | J7: ='[2]data summary'!P26 -> 0.0065249845 | K7: ='[2]data summary'!Q26 -> 0.0025733833 | L7: ='[2]data summary'!R26 -> 0 | M7: ='[2]data summary'!S26 -> 0.0053189608 | N7: ='[2]data summary'!T26 -> 0.0005330848 | ... S7: ='[2]data summary'!Y26 -> 0.0021518609
A8: ='[1]data summary'!A37 -> 0 | B8: ='[1]data summary'!B37 -> Sur | C8: ='[1]data summary'!C37 -> 224617.65 | D8: ='[1]data summary'!D37 -> 0.027020231 | E8: ='[1]data summary'!E37 -> 2242851.1 | G8: ='[2]data summary'!M27 -> 0 | H8: ='[2]data summary'!N27 -> Solid | I8: ='[2]data summary'!O27 -> 0.07715369 | J8: ='[2]data summary'!P27 -> 0.0077371707 | K8: ='[2]data summary'!Q27 -> 0.0030505019 | L8: ='[2]data summary'!R27 -> 0 | M8: ='[2]data summary'!S27 -> 0.0063050399 | N8: ='[2]data summary'!T27 -> 0.0006321105 | ... S8: ='[2]data summary'!Y27 -> 0.0025508231
A9: ='[1]data summary'!A38 -> 0 | B9: ='[1]data summary'!B38 -> TARC | C9: ='[1]data summary'!C38 -> 11780121 | D9: ='[1]data summary'!D38 -> 1.3875143 | E9: ='[1]data summary'!E38 -> 1.1629951e+08 | G9: ='[2]data summary'!M28 -> 0 | H9: ='[2]data summary'!N28 -> Solvent | I9: ='[2]data summary'!O28 -> 7.7757772 | J9: ='[2]data summary'!P28 -> 0.77944907 | K9: ='[2]data summary'!Q28 -> 0.30743861 | L9: ='[2]data summary'!R28 -> 0 | M9: ='[2]data summary'!S28 -> 0.40990547 | N9: ='[2]data summary'!T28 -> 0.041134487 | ... S9: ='[2]data summary'!Y28 -> 0.23609889
A10: ='[1]data summary'!A39 -> 0 | B10: ='[1]data summary'!B39 -> Polymer | C10: ='[1]data summary'!C39 -> 286208.05 | D10: ='[1]data summary'!D39 -> 0.016232341 | E10: ='[1]data summary'!E39 -> 2038811.2 | G10: ='[2]data summary'!M29 -> 0 | H10: ='[2]data summary'!N29 -> Water | I10: ='[2]data summary'!O29 -> 17.374113 | J10: ='[2]data summary'!P29 -> 1.7432502 | K10: ='[2]data summary'!Q29 -> 0.68693751 | L10: ='[2]data summary'!R29 -> 0 | M10: ='[2]data summary'!S29 -> 2.10137 | N10: ='[2]data summary'!T29 -> 0.21043305 | ... S10: ='[2]data summary'!Y29 -> 0.75919842
A11: ='[1]data summary'!A40 -> 0 | B11: ='[1]data summary'!B40 -> ITC | C11: ='[1]data summary'!C40 -> 6193782 | D11: ='[1]data summary'!D40 -> 0.70621839 | E11: ='[1]data summary'!E40 -> 60109138 | G11: ='[2]data summary'!M30 -> 0 | H11: ='[2]data summary'!N30 -> 0 | I11: ='[2]data summary'!O30 -> 25.29213 | J11: ='[2]data summary'!P30 -> 2.5369614 | K11: ='[2]data summary'!Q30 -> 0 | L11: ='[2]data summary'!R30 -> 0 | M11: ='[2]data summary'!S30 -> 2.5228994 | N11: ='[2]data summary'!T30 -> 0.25273273 | ... S11: ='[2]data summary'!Y30 -> 0
A12: ='[1]data summary'!A41 -> 0 | B12: ='[1]data summary'!B41 -> PBO | C12: ='[1]data summary'!C41 -> 2555997.8 | D12: ='[1]data summary'!D41 -> 0.14010064 | E12: ='[1]data summary'!E41 -> 18011777 | G12: ='[2]data summary'!M31 -> 0 | H12: ='[2]data summary'!N31 -> 0 | I12: ='[2]data summary'!O31 -> 0 | J12: ='[2]data summary'!P31 -> 0 | K12: ='[2]data summary'!Q31 -> 0 | L12: ='[2]data summary'!R31 -> 0 | M12: ='[2]data summary'!S31 -> 0 | N12: ='[2]data summary'!T31 -> 0 | ... S12: ='[2]data summary'!Y31 -> 0
A13: ='[1]data summary'!A42 -> 0 | B13: ='[1]data summary'!B42 -> 0 | C13: ='[1]data summary'!C42 -> 25292130 | D13: ='[1]data summary'!D42 -> 2.5228994 | E13: ='[1]data summary'!E42 -> 2.2919877e+08 | G13: ='[2]data summary'!M32 -> 2030 | H13: ='[2]data summary'!N32 -> Gas | I13: ='[2]data summary'!O32 -> 0.4600892 | J13: ='[2]data summary'!P32 -> 0.051349007 | K13: ='[2]data summary'!Q32 -> 0.0025552637 | L13: ='[2]data summary'!R32 -> 0 | M13: ='[2]data summary'!S32 -> 0.035769125 | N13: ='[2]data summary'!T32 -> 0.0039889688 | ... S13: ='[2]data summary'!Y32 -> 0.0021466589
A14: ='[1]data summary'!A43 -> 0 | B14: ='[1]data summary'!B43 -> 0 | C14: ='[1]data summary'!C43 -> 0 | D14: ='[1]data summary'!D43 -> 0 | E14: ='[1]data summary'!E43 -> 0 | G14: ='[2]data summary'!M33 -> 0 | H14: ='[2]data summary'!N33 -> Solid | I14: ='[2]data summary'!O33 -> 0.59371643 | J14: ='[2]data summary'!P33 -> 0.066254558 | K14: ='[2]data summary'!Q33 -> 0.0032974085 | L14: ='[2]data summary'!R33 -> 0 | M14: ='[2]data summary'!S33 -> 0.046156295 | N14: ='[2]data summary'!T33 -> 0.005146719 | ... S14: ='[2]data summary'!Y33 -> 0.0027701193
A15: ='[1]data summary'!A44 -> 2030 | B15: ='[1]data summary'!B44 -> PAG | C15: ='[1]data summary'!C44 -> 30470469 | D15: ='[1]data summary'!D44 -> 1.6330718 | E15: ='[1]data summary'!E44 -> 2.1749867e+08 | G15: ='[2]data summary'!M34 -> 0 | H15: ='[2]data summary'!N34 -> Solvent | I15: ='[2]data summary'!O34 -> 60.863622 | J15: ='[2]data summary'!P34 -> 6.7393192 | K15: ='[2]data summary'!Q34 -> 0.33802706 | L15: ='[2]data summary'!R34 -> 0 | M15: ='[2]data summary'!S34 -> 2.9853935 | N15: ='[2]data summary'!T34 -> 0.33673238 | ... S15: ='[2]data summary'!Y34 -> 0.26146467
A16: ='[1]data summary'!A45 -> 0 | B16: ='[1]data summary'!B45 -> Sur | C16: ='[1]data summary'!C45 -> 1492142.3 | D16: ='[1]data summary'!D45 -> 0.16877955 | E16: ='[1]data summary'!E45 -> 14913965 | G16: ='[2]data summary'!M35 -> 0 | H16: ='[2]data summary'!N35 -> Water | I16: ='[2]data summary'!O35 -> 118.13804 | J16: ='[2]data summary'!P35 -> 13.432348 | K16: ='[2]data summary'!Q35 -> 0.65612027 | L16: ='[2]data summary'!R35 -> 0 | M16: ='[2]data summary'!S35 -> 13.441604 | N16: ='[2]data summary'!T35 -> 1.4930943 | ... S16: ='[2]data summary'!Y35 -> 0.73361855
A17: ='[1]data summary'!A46 -> 0 | B17: ='[1]data summary'!B46 -> TARC | C17: ='[1]data summary'!C46 -> 80653744 | D17: ='[1]data summary'!D46 -> 8.9147865 | E17: ='[1]data summary'!E46 -> 7.9620267e+08 | G17: ='[2]data summary'!M36 -> 0 | H17: ='[2]data summary'!N36 -> 0 | I17: ='[2]data summary'!O36 -> 180.05547 | J17: ='[2]data summary'!P36 -> 20.289271 | K17: ='[2]data summary'!Q36 -> 0 | L17: ='[2]data summary'!R36 -> 0 | M17: ='[2]data summary'!S36 -> 16.508922 | N17: ='[2]data summary'!T36 -> 1.8389624 | ... S17: ='[2]data summary'!Y36 -> 0
... A20: ='[1]data summary'!A49 -> 0 | B20: ='[1]data summary'!B49 -> PBO | C20: ='[1]data summary'!C49 -> 23175498 | D20: ='[1]data summary'!D49 -> 1.1799188 | E20: ='[1]data summary'!E49 -> 1.6267299e+08 | G20: ='[2]data summary'!M39 -> 2030 | H20: ='[2]data summary'!N39 -> 0 | I20: ='[2]data summary'!O39 -> 180.05547 | J20: ='[2]data summary'!P39 -> 20.289271 | K20: ='[2]data summary'!Q39 -> 0 | L20: ='[2]data summary'!R39 -> 0 | M20: ='[2]data summary'!S39 -> 16.508922 | N20: ='[2]data summary'!T39 -> 1.8389624 | ... S20: ='[2]data summary'!Y39 -> 0
A21: ='[1]data summary'!A50 -> 0 | B21: ='[1]data summary'!B50 -> 0 | C21: ='[1]data summary'!C50 -> 1.8005547e+08 | D21: ='[1]data summary'!D50 -> 16.508922 | E21: ='[1]data summary'!E50 -> 1.6148622e+09
A25: 13MJ
A26: ='[3]data summary'!A35 -> yearly | B26: ='[3]data summary'!B35 -> 0 | C26: ='[3]data summary'!C35 -> CC | D26: ='[3]data summary'!D35 -> HTC | E26: ='[3]data summary'!E35 -> CED | G26: ='[4]data summary'!M25 -> 0 | H26: ='[4]data summary'!N25 -> 0 | I26: ='[4]data summary'!O25 -> CC | J26: ='[4]data summary'!P25 -> CC | K26: ='[4]data summary'!Q25 -> 0 | L26: ='[4]data summary'!R25 -> 0 | M26: ='[4]data summary'!S25 -> HTC | N26: ='[4]data summary'!T25 -> HTC | ... S26: ='[4]data summary'!Y25 -> 0
A27: ='[3]data summary'!A36 -> 2025 | B27: ='[3]data summary'!B36 -> PAG | C27: ='[3]data summary'!C36 -> 4250269.7 | D27: ='[3]data summary'!D36 -> 0.2457797 | E27: ='[3]data summary'!E36 -> 30549096 | G27: ='[4]data summary'!M26 -> 2025 | H27: ='[4]data summary'!N26 -> Gas | I27: ='[4]data summary'!O26 -> 0.064930173 | J27: ='[4]data summary'!P26 -> 0.0063416264 | K27: ='[4]data summary'!Q26 -> 0.0025171708 | L27: ='[4]data summary'!R26 -> 0 | M27: ='[4]data summary'!S26 -> 0.0053061891 | N27: ='[4]data summary'!T26 -> 0.00051812995 | ... S27: ='[4]data summary'!Y26 -> 0.0020808285
A28: ='[3]data summary'!A37 -> 0 | B28: ='[3]data summary'!B37 -> Sur | C28: ='[3]data summary'!C37 -> 231289.73 | D28: ='[3]data summary'!D37 -> 0.027397986 | E28: ='[3]data summary'!E37 -> 2337360.9 | G28: ='[4]data summary'!M27 -> 0 | H28: ='[4]data summary'!N27 -> Solid | I28: ='[4]data summary'!O27 -> 0.076968834 | J28: ='[4]data summary'!P27 -> 0.0075190383 | K28: ='[4]data summary'!Q27 -> 0.0029838777 | L28: ='[4]data summary'!R27 -> 0 | M28: ='[4]data summary'!S27 -> 0.0062899225 | N28: ='[4]data summary'!T27 -> 0.00061431954 | ... S28: ='[4]data summary'!Y27 -> 0.0024666297
A29: ='[3]data summary'!A38 -> 0 | B29: ='[3]data summary'!B38 -> TARC | C29: ='[3]data summary'!C38 -> 12115842 | D29: ='[3]data summary'!D38 -> 1.4065219 | E29: ='[3]data summary'!E38 -> 1.2106292e+08 | G29: ='[4]data summary'!M28 -> 0 | H29: ='[4]data summary'!N28 -> Solvent | I29: ='[4]data summary'!O28 -> 7.7571622 | J29: ='[4]data summary'!P28 -> 0.75743878 | K29: ='[4]data summary'!Q28 -> 0.30072462 | L29: ='[4]data summary'!R28 -> 0 | M29: ='[4]data summary'!S28 -> 0.40892315 | N29: ='[4]data summary'!T28 -> 0.039975058 | ... S29: ='[4]data summary'!Y28 -> 0.2283066
A30: ='[3]data summary'!A39 -> 0 | B30: ='[3]data summary'!B39 -> Polymer | C30: ='[3]data summary'!C39 -> 285979.57 | D30: ='[3]data summary'!D39 -> 0.016221482 | E30: ='[3]data summary'!E39 -> 2040265.9 | G30: ='[4]data summary'!M29 -> 0 | H30: ='[4]data summary'!N29 -> Water | I30: ='[4]data summary'!O29 -> 17.895841 | J30: ='[4]data summary'!P29 -> 1.7494598 | K30: ='[4]data summary'!Q29 -> 0.69377433 | L30: ='[4]data summary'!R29 -> 0 | M30: ='[4]data summary'!S29 -> 2.1309063 | N30: ='[4]data summary'!T29 -> 0.20793769 | ... S30: ='[4]data summary'!Y29 -> 0.76714594
A31: ='[3]data summary'!A40 -> 0 | B31: ='[3]data summary'!B40 -> ITC | C31: ='[3]data summary'!C40 -> 6359396 | D31: ='[3]data summary'!D40 -> 0.71560199 | E31: ='[3]data summary'!E40 -> 62464832 | G31: ='[4]data summary'!M30 -> 0 | H31: ='[4]data summary'!N30 -> 0 | I31: ='[4]data summary'!O30 -> 25.794902 | J31: ='[4]data summary'!P30 -> 2.5207592 | K31: ='[4]data summary'!Q30 -> 0 | L31: ='[4]data summary'!R30 -> 0 | M31: ='[4]data summary'!S30 -> 2.5514256 | N31: ='[4]data summary'!T30 -> 0.2490452 | ... S31: ='[4]data summary'!Y30 -> 0
A32: ='[3]data summary'!A41 -> 0 | B32: ='[3]data summary'!B41 -> PBO | C32: ='[3]data summary'!C41 -> 2552124.6 | D32: ='[3]data summary'!D41 -> 0.13990257 | E32: ='[3]data summary'!E41 -> 17999584 | G32: ='[4]data summary'!M31 -> 0 | H32: ='[4]data summary'!N31 -> 0 | I32: ='[4]data summary'!O31 -> 0 | J32: ='[4]data summary'!P31 -> 0 | K32: ='[4]data summary'!Q31 -> 0 | L32: ='[4]data summary'!R31 -> 0 | M32: ='[4]data summary'!S31 -> 0 | N32: ='[4]data summary'!T31 -> 0 | ... S32: ='[4]data summary'!Y31 -> 0
A33: ='[3]data summary'!A42 -> 0 | B33: ='[3]data summary'!B42 -> 0 | C33: ='[3]data summary'!C42 -> 25794902 | D33: ='[3]data summary'!D42 -> 2.5514256 | E33: ='[3]data summary'!E42 -> 2.3645406e+08 | G33: ='[4]data summary'!M32 -> 2030 | H33: ='[4]data summary'!N32 -> Gas | I33: ='[4]data summary'!O32 -> 0.45865562 | J33: ='[4]data summary'!P32 -> 0.051337499 | K33: ='[4]data summary'!Q32 -> 0.002497243 | L33: ='[4]data summary'!R32 -> 0 | M33: ='[4]data summary'!S32 -> 0.035657686 | N33: ='[4]data summary'!T32 -> 0.0039877199 | ... S33: ='[4]data summary'!Y32 -> 0.0020719191
A34: ='[3]data summary'!A43 -> 0 | B34: ='[3]data summary'!B43 -> 0 | C34: ='[3]data summary'!C43 -> 0 | D34: ='[3]data summary'!D43 -> 0 | E34: ='[3]data summary'!E43 -> 0 | G34: ='[4]data summary'!M33 -> 0 | H34: ='[4]data summary'!N33 -> Solid | I34: ='[4]data summary'!O33 -> 0.59186568 | J34: ='[4]data summary'!P33 -> 0.066260945 | K34: ='[4]data summary'!Q33 -> 0.003222532 | L34: ='[4]data summary'!R33 -> 0 | M34: ='[4]data summary'!S33 -> 0.046012431 | N34: ='[4]data summary'!T33 -> 0.0051467551 | ... S34: ='[4]data summary'!Y33 -> 0.0026736689
A35: ='[3]data summary'!A44 -> 2030 | B35: ='[3]data summary'!B44 -> PAG | C35: ='[3]data summary'!C44 -> 30441013 | D35: ='[3]data summary'!D44 -> 1.6315627 | E35: ='[3]data summary'!E44 -> 2.1773286e+08 | G35: ='[4]data summary'!M34 -> 0 | H35: ='[4]data summary'!N34 -> Solvent | I35: ='[4]data summary'!O34 -> 60.673895 | J35: ='[4]data summary'!P34 -> 6.7399035 | K35: ='[4]data summary'!Q34 -> 0.33035126 | L35: ='[4]data summary'!R34 -> 0 | M35: ='[4]data summary'!S34 -> 2.9760888 | N35: ='[4]data summary'!T34 -> 0.33672926 | ... S35: ='[4]data summary'!Y34 -> 0.25236096
A36: ='[3]data summary'!A45 -> 0 | B36: ='[3]data summary'!B45 -> Sur | C36: ='[3]data summary'!C45 -> 1539589.9 | D36: ='[3]data summary'!D45 -> 0.17110059 | E36: ='[3]data summary'!E45 -> 15592918 | G36: ='[4]data summary'!M35 -> 0 | H36: ='[4]data summary'!N35 -> Water | I36: ='[4]data summary'!O35 -> 121.94038 | J36: ='[4]data summary'!P35 -> 13.892786 | K36: ='[4]data summary'!Q35 -> 0.66392897 | L36: ='[4]data summary'!R35 -> 0 | M36: ='[4]data summary'!S35 -> 13.627609 | N36: ='[4]data summary'!T35 -> 1.518219 | ... S36: ='[4]data summary'!Y35 -> 0.74289346
A37: ='[3]data summary'!A46 -> 0 | B37: ='[3]data summary'!B46 -> TARC | C37: ='[3]data summary'!C46 -> 83104917 | D37: ='[3]data summary'!D46 -> 9.0346776 | E37: ='[3]data summary'!E46 -> 8.3135292e+08 | G37: ='[4]data summary'!M36 -> 0 | H37: ='[4]data summary'!N36 -> 0 | I37: ='[4]data summary'!O36 -> 183.66479 | J37: ='[4]data summary'!P36 -> 20.750288 | K37: ='[4]data summary'!Q36 -> 0 | L37: ='[4]data summary'!R36 -> 0 | M37: ='[4]data summary'!S36 -> 16.685368 | N37: ='[4]data summary'!T36 -> 1.8640827 | ... S37: ='[4]data summary'!Y36 -> 0
... A40: ='[3]data summary'!A49 -> 0 | B40: ='[3]data summary'!B49 -> PBO | C40: ='[3]data summary'!C49 -> 23123423 | D40: ='[3]data summary'!D49 -> 1.1773434 | E40: ='[3]data summary'!E49 -> 1.6244706e+08 | G40: ='[4]data summary'!M39 -> 2030 | H40: ='[4]data summary'!N39 -> 0 | I40: ='[4]data summary'!O39 -> 183.66479 | J40: ='[4]data summary'!P39 -> 20.750288 | K40: ='[4]data summary'!Q39 -> 0 | L40: ='[4]data summary'!R39 -> 0 | M40: ='[4]data summary'!S39 -> 16.685368 | N40: ='[4]data summary'!T39 -> 1.8640827 | ... S40: ='[4]data summary'!Y39 -> 0
A41: ='[3]data summary'!A50 -> 0 | B41: ='[3]data summary'!B50 -> 0 | C41: ='[3]data summary'!C50 -> 1.8366479e+08 | D41: ='[3]data summary'!D50 -> 16.685368 | E41: ='[3]data summary'!E50 -> 1.6679015e+09
A45: {=INDEX($A$6:$S$41, COLUMN(A1), ROW(A1))} -> yearly | B45: {=INDEX($A$6:$S$41, COLUMN(B1), ROW(B1))} -> 2025 | C45: {=INDEX($A$6:$S$41, COLUMN(C1), ROW(C1))} -> 0 | D45: {=INDEX($A$6:$S$41, COLUMN(D1), ROW(D1))} -> 0 | E45: {=INDEX($A$6:$S$41, COLUMN(E1), ROW(E1))} -> 0 | F45: {=INDEX($A$6:$S$41, COLUMN(F1), ROW(F1))} -> 0 | G45: {=INDEX($A$6:$S$41, COLUMN(G1), ROW(G1))} -> 0 | H45: {=INDEX($A$6:$S$41, COLUMN(H1), ROW(H1))} -> 0 | ... AJ45: {=INDEX($A$6:$S$41, COLUMN(AJ1), ROW(AJ1))} -> 0
A46: {=INDEX($A$6:$S$41, COLUMN(A2), ROW(A2))} -> 0 | B46: {=INDEX($A$6:$S$41, COLUMN(B2), ROW(B2))} -> PAG | C46: {=INDEX($A$6:$S$41, COLUMN(C2), ROW(C2))} -> Sur | D46: {=INDEX($A$6:$S$41, COLUMN(D2), ROW(D2))} -> TARC | E46: {=INDEX($A$6:$S$41, COLUMN(E2), ROW(E2))} -> Polymer | F46: {=INDEX($A$6:$S$41, COLUMN(F2), ROW(F2))} -> ITC | G46: {=INDEX($A$6:$S$41, COLUMN(G2), ROW(G2))} -> PBO | H46: {=INDEX($A$6:$S$41, COLUMN(H2), ROW(H2))} -> 0 | ... AJ46: {=INDEX($A$6:$S$41, COLUMN(AJ2), ROW(AJ2))} -> 0
A47: {=INDEX($A$6:$S$41, COLUMN(A3), ROW(A3))} -> CC | B47: {=INDEX($A$6:$S$41, COLUMN(B3), ROW(B3))} -> 4251403.3 | C47: {=INDEX($A$6:$S$41, COLUMN(C3), ROW(C3))} -> 224617.65 | D47: {=INDEX($A$6:$S$41, COLUMN(D3), ROW(D3))} -> 11780121 | E47: {=INDEX($A$6:$S$41, COLUMN(E3), ROW(E3))} -> 286208.05 | F47: {=INDEX($A$6:$S$41, COLUMN(F3), ROW(F3))} -> 6193782 | G47: {=INDEX($A$6:$S$41, COLUMN(G3), ROW(G3))} -> 2555997.8 | H47: {=INDEX($A$6:$S$41, COLUMN(H3), ROW(H3))} -> 25292130 | ... AJ47: {=INDEX($A$6:$S$41, COLUMN(AJ3), ROW(AJ3))} -> 1.8366479e+08
A48: {=INDEX($A$6:$S$41, COLUMN(A4), ROW(A4))} -> HTC | B48: {=INDEX($A$6:$S$41, COLUMN(B4), ROW(B4))} -> 0.24581354 | C48: {=INDEX($A$6:$S$41, COLUMN(C4), ROW(C4))} -> 0.027020231 | D48: {=INDEX($A$6:$S$41, COLUMN(D4), ROW(D4))} -> 1.3875143 | E48: {=INDEX($A$6:$S$41, COLUMN(E4), ROW(E4))} -> 0.016232341 | F48: {=INDEX($A$6:$S$41, COLUMN(F4), ROW(F4))} -> 0.70621839 | G48: {=INDEX($A$6:$S$41, COLUMN(G4), ROW(G4))} -> 0.14010064 | H48: {=INDEX($A$6:$S$41, COLUMN(H4), ROW(H4))} -> 2.5228994 | ... AJ48: {=INDEX($A$6:$S$41, COLUMN(AJ4), ROW(AJ4))} -> 16.685368
A49: {=INDEX($A$6:$S$41, COLUMN(A5), ROW(A5))} -> CED | B49: {=INDEX($A$6:$S$41, COLUMN(B5), ROW(B5))} -> 30496685 | C49: {=INDEX($A$6:$S$41, COLUMN(C5), ROW(C5))} -> 2242851.1 | D49: {=INDEX($A$6:$S$41, COLUMN(D5), ROW(D5))} -> 1.1629951e+08 | E49: {=INDEX($A$6:$S$41, COLUMN(E5), ROW(E5))} -> 2038811.2 | F49: {=INDEX($A$6:$S$41, COLUMN(F5), ROW(F5))} -> 60109138 | G49: {=INDEX($A$6:$S$41, COLUMN(G5), ROW(G5))} -> 18011777 | H49: {=INDEX($A$6:$S$41, COLUMN(H5), ROW(H5))} -> 2.2919877e+08 | ... AJ49: {=INDEX($A$6:$S$41, COLUMN(AJ5), ROW(AJ5))} -> 1.6679015e+09
A50: {=INDEX($A$6:$S$41, COLUMN(A6), ROW(A6))} -> 0 | B50: {=INDEX($A$6:$S$41, COLUMN(B6), ROW(B6))} -> 0 | C50: {=INDEX($A$6:$S$41, COLUMN(C6), ROW(C6))} -> 0 | D50: {=INDEX($A$6:$S$41, COLUMN(D6), ROW(D6))} -> 0 | E50: {=INDEX($A$6:$S$41, COLUMN(E6), ROW(E6))} -> 0 | F50: {=INDEX($A$6:$S$41, COLUMN(F6), ROW(F6))} -> 0 | G50: {=INDEX($A$6:$S$41, COLUMN(G6), ROW(G6))} -> 0 | H50: {=INDEX($A$6:$S$41, COLUMN(H6), ROW(H6))} -> 0 | ... AJ50: {=INDEX($A$6:$S$41, COLUMN(AJ6), ROW(AJ6))} -> 0
A51: {=INDEX($A$6:$S$41, COLUMN(A7), ROW(A7))} -> 0 | B51: {=INDEX($A$6:$S$41, COLUMN(B7), ROW(B7))} -> 2025 | C51: {=INDEX($A$6:$S$41, COLUMN(C7), ROW(C7))} -> 0 | D51: {=INDEX($A$6:$S$41, COLUMN(D7), ROW(D7))} -> 0 | E51: {=INDEX($A$6:$S$41, COLUMN(E7), ROW(E7))} -> 0 | F51: {=INDEX($A$6:$S$41, COLUMN(F7), ROW(F7))} -> 0 | G51: {=INDEX($A$6:$S$41, COLUMN(G7), ROW(G7))} -> 0 | H51: {=INDEX($A$6:$S$41, COLUMN(H7), ROW(H7))} -> 2030 | ... AJ51: {=INDEX($A$6:$S$41, COLUMN(AJ7), ROW(AJ7))} -> 0
A52: {=INDEX($A$6:$S$41, COLUMN(A8), ROW(A8))} -> 0 | B52: {=INDEX($A$6:$S$41, COLUMN(B8), ROW(B8))} -> Gas | C52: {=INDEX($A$6:$S$41, COLUMN(C8), ROW(C8))} -> Solid | D52: {=INDEX($A$6:$S$41, COLUMN(D8), ROW(D8))} -> Solvent | E52: {=INDEX($A$6:$S$41, COLUMN(E8), ROW(E8))} -> Water | F52: {=INDEX($A$6:$S$41, COLUMN(F8), ROW(F8))} -> 0 | G52: {=INDEX($A$6:$S$41, COLUMN(G8), ROW(G8))} -> 0 | H52: {=INDEX($A$6:$S$41, COLUMN(H8), ROW(H8))} -> Gas | ... AJ52: {=INDEX($A$6:$S$41, COLUMN(AJ8), ROW(AJ8))} -> 0
A53: {=INDEX($A$6:$S$41, COLUMN(A9), ROW(A9))} -> CC | B53: {=INDEX($A$6:$S$41, COLUMN(B9), ROW(B9))} -> 0.065086345 | C53: {=INDEX($A$6:$S$41, COLUMN(C9), ROW(C9))} -> 0.07715369 | D53: {=INDEX($A$6:$S$41, COLUMN(D9), ROW(D9))} -> 7.7757772 | E53: {=INDEX($A$6:$S$41, COLUMN(E9), ROW(E9))} -> 17.374113 | F53: {=INDEX($A$6:$S$41, COLUMN(F9), ROW(F9))} -> 25.29213 | G53: {=INDEX($A$6:$S$41, COLUMN(G9), ROW(G9))} -> 0 | H53: {=INDEX($A$6:$S$41, COLUMN(H9), ROW(H9))} -> 0.4600892 | ... AJ53: {=INDEX($A$6:$S$41, COLUMN(AJ9), ROW(AJ9))} -> 0
A54: {=INDEX($A$6:$S$41, COLUMN(A10), ROW(A10))} -> CC | B54: {=INDEX($A$6:$S$41, COLUMN(B10), ROW(B10))} -> 0.0065249845 | C54: {=INDEX($A$6:$S$41, COLUMN(C10), ROW(C10))} -> 0.0077371707 | D54: {=INDEX($A$6:$S$41, COLUMN(D10), ROW(D10))} -> 0.77944907 | E54: {=INDEX($A$6:$S$41, COLUMN(E10), ROW(E10))} -> 1.7432502 | F54: {=INDEX($A$6:$S$41, COLUMN(F10), ROW(F10))} -> 2.5369614 | G54: {=INDEX($A$6:$S$41, COLUMN(G10), ROW(G10))} -> 0 | H54: {=INDEX($A$6:$S$41, COLUMN(H10), ROW(H10))} -> 0.051349007 | ... AJ54: {=INDEX($A$6:$S$41, COLUMN(AJ10), ROW(AJ10))} -> 0
...

Sheet 2-better separation
A5: 1.5
A6: ='[5]data summary'!A35 -> yearly | B6: ='[5]data summary'!B35 -> 0 | C6: ='[5]data summary'!C35 -> CC | D6: ='[5]data summary'!D35 -> HTC | E6: ='[5]data summary'!E35 -> CED | G6: ='[6]data summary'!M25 -> 0 | H6: ='[6]data summary'!N25 -> 0 | I6: ='[6]data summary'!O25 -> CC | J6: ='[6]data summary'!P25 -> CC | K6: ='[6]data summary'!Q25 -> 0 | L6: ='[6]data summary'!R25 -> 0 | M6: ='[6]data summary'!S25 -> HTC | N6: ='[6]data summary'!T25 -> HTC | ... S6: ='[6]data summary'!Y25 -> 0
A7: ='[5]data summary'!A36 -> 2025 | B7: ='[5]data summary'!B36 -> PAG | C7: ='[5]data summary'!C36 -> 4225983.1 | D7: ='[5]data summary'!D36 -> 0.24000977 | E7: ='[5]data summary'!E36 -> 30261196 | G7: ='[6]data summary'!M26 -> 2025 | H7: ='[6]data summary'!N26 -> Gas | I7: ='[6]data summary'!O26 -> 0.065047028 | J7: ='[6]data summary'!P26 -> 0.0063929236 | K7: ='[6]data summary'!Q26 -> 0.0027266437 | L7: ='[6]data summary'!R26 -> 0 | M7: ='[6]data summary'!S26 -> 0.0053157365 | N7: ='[6]data summary'!T26 -> 0.000522313 | ... S7: ='[6]data summary'!Y26 -> 0.0022865746
A8: ='[5]data summary'!A37 -> 0 | B8: ='[5]data summary'!B37 -> Sur | C8: ='[5]data summary'!C37 -> 206300.64 | D8: ='[5]data summary'!D37 -> 0.022505514 | E8: ='[5]data summary'!E37 -> 2068804.4 | G8: ='[6]data summary'!M27 -> 0 | H8: ='[6]data summary'!N27 -> Solid | I8: ='[6]data summary'!O27 -> 0.077107402 | J8: ='[6]data summary'!P27 -> 0.0075800997 | K8: ='[6]data summary'!Q27 -> 0.0032321909 | L8: ='[6]data summary'!R27 -> 0 | M8: ='[6]data summary'!S27 -> 0.0063012438 | N8: ='[6]data summary'!T27 -> 0.00061929897 | ... S8: ='[6]data summary'!Y27 -> 0.0027105244
A9: ='[5]data summary'!A38 -> 0 | B9: ='[5]data summary'!B38 -> TARC | C9: ='[5]data summary'!C38 -> 10854831 | D9: ='[5]data summary'!D38 -> 1.159527 | E9: ='[5]data summary'!E38 -> 1.0750802e+08 | G9: ='[6]data summary'!M28 -> 0 | H9: ='[6]data summary'!N28 -> Solvent | I9: ='[6]data summary'!O28 -> 7.7711305 | J9: ='[6]data summary'!P28 -> 0.76360161 | K9: ='[6]data summary'!Q28 -> 0.32575053 | L9: ='[6]data summary'!R28 -> 0 | M9: ='[6]data summary'!S28 -> 0.40965925 | N9: ='[6]data summary'!T28 -> 0.040299645 | ... S9: ='[6]data summary'!Y28 -> 0.25088114
A10: ='[5]data summary'!A39 -> 0 | B10: ='[5]data summary'!B39 -> Polymer | C10: ='[5]data summary'!C39 -> 284880.4 | D10: ='[5]data summary'!D39 -> 0.015936741 | E10: ='[5]data summary'!E39 -> 2026610.6 | G10: ='[6]data summary'!M29 -> 0 | H10: ='[6]data summary'!N29 -> Water | I10: ='[6]data summary'!O29 -> 15.942794 | J10: ='[6]data summary'!P29 -> 1.5678221 | K10: ='[6]data summary'!Q29 -> 0.66829063 | L10: ='[6]data summary'!R29 -> 0 | M10: ='[6]data summary'!S29 -> 1.7485774 | N10: ='[6]data summary'!T29 -> 0.17170309 | ... S10: ='[6]data summary'!Y29 -> 0.74412176
A11: ='[5]data summary'!A40 -> 0 | B11: ='[5]data summary'!B40 -> ITC | C11: ='[5]data summary'!C40 -> 5735174.8 | D11: ='[5]data summary'!D40 -> 0.59324028 | E11: ='[5]data summary'!E40 -> 55752417 | G11: ='[6]data summary'!M30 -> 0 | H11: ='[6]data summary'!N30 -> 0 | I11: ='[6]data summary'!O30 -> 23.856079 | J11: ='[6]data summary'!P30 -> 2.3453968 | K11: ='[6]data summary'!Q30 -> 0 | L11: ='[6]data summary'!R30 -> 0 | M11: ='[6]data summary'!S30 -> 2.1698536 | N11: ='[6]data summary'!T30 -> 0.21314435 | ... S11: ='[6]data summary'!Y30 -> 0
A12: ='[5]data summary'!A41 -> 0 | B12: ='[5]data summary'!B41 -> PBO | C12: ='[5]data summary'!C41 -> 2548908.9 | D12: ='[5]data summary'!D41 -> 0.13863426 | E12: ='[5]data summary'!E41 -> 17948111 | G12: ='[6]data summary'!M31 -> 0 | H12: ='[6]data summary'!N31 -> 0 | I12: ='[6]data summary'!O31 -> 0 | J12: ='[6]data summary'!P31 -> 0 | K12: ='[6]data summary'!Q31 -> 0 | L12: ='[6]data summary'!R31 -> 0 | M12: ='[6]data summary'!S31 -> 0 | N12: ='[6]data summary'!T31 -> 0 | ... S12: ='[6]data summary'!Y31 -> 0
A13: ='[5]data summary'!A42 -> 0 | B13: ='[5]data summary'!B42 -> 0 | C13: ='[5]data summary'!C42 -> 23856079 | D13: ='[5]data summary'!D42 -> 2.1698536 | E13: ='[5]data summary'!E42 -> 2.1556515e+08 | G13: ='[6]data summary'!M32 -> 2030 | H13: ='[6]data summary'!N32 -> Gas | I13: ='[6]data summary'!O32 -> 0.45877705 | J13: ='[6]data summary'!P32 -> 0.051149155 | K13: ='[6]data summary'!Q32 -> 0.0026699188 | L13: ='[6]data summary'!R32 -> 0 | M13: ='[6]data summary'!S32 -> 0.035667166 | N13: ='[6]data summary'!T32 -> 0.0039733552 | ... S13: ='[6]data summary'!Y32 -> 0.0022459707
A14: ='[5]data summary'!A43 -> 0 | B14: ='[5]data summary'!B43 -> 0 | C14: ='[5]data summary'!C43 -> 0 | D14: ='[5]data summary'!D43 -> 0 | E14: ='[5]data summary'!E43 -> 0 | G14: ='[6]data summary'!M33 -> 0 | H14: ='[6]data summary'!N33 -> Solid | I14: ='[6]data summary'!O33 -> 0.59201999 | J14: ='[6]data summary'!P33 -> 0.066001954 | K14: ='[6]data summary'!Q33 -> 0.0034453451 | L14: ='[6]data summary'!R33 -> 0 | M14: ='[6]data summary'!S33 -> 0.046024475 | N14: ='[6]data summary'!T33 -> 0.0051269809 | ... S14: ='[6]data summary'!Y33 -> 0.0028982587
A15: ='[5]data summary'!A44 -> 2030 | B15: ='[5]data summary'!B44 -> PAG | C15: ='[5]data summary'!C44 -> 30262478 | D15: ='[5]data summary'!D44 -> 1.5948825 | E15: ='[5]data summary'!E44 -> 2.1576015e+08 | G15: ='[6]data summary'!M34 -> 0 | H15: ='[6]data summary'!N34 -> Solvent | I15: ='[6]data summary'!O34 -> 60.689713 | J15: ='[6]data summary'!P34 -> 6.7136091 | K15: ='[6]data summary'!Q34 -> 0.35319248 | L15: ='[6]data summary'!R34 -> 0 | M15: ='[6]data summary'!S34 -> 2.9768692 | N15: ='[6]data summary'!T34 -> 0.33543965 | ... S15: ='[6]data summary'!Y34 -> 0.27355942
A16: ='[5]data summary'!A45 -> 0 | B16: ='[5]data summary'!B45 -> Sur | C16: ='[5]data summary'!C45 -> 1391571.3 | D16: ='[5]data summary'!D45 -> 0.14162188 | E16: ='[5]data summary'!E45 -> 13981956 | G16: ='[6]data summary'!M35 -> 0 | H16: ='[6]data summary'!N35 -> Water | I16: ='[6]data summary'!O35 -> 110.09133 | J16: ='[6]data summary'!P35 -> 12.434548 | K16: ='[6]data summary'!Q35 -> 0.64069226 | L16: ='[6]data summary'!R35 -> 0 | M16: ='[6]data summary'!S35 -> 11.267858 | N16: ='[6]data summary'!T35 -> 1.2513755 | ... S16: ='[6]data summary'!Y35 -> 0.72129636
A17: ='[5]data summary'!A46 -> 0 | B17: ='[5]data summary'!B46 -> TARC | C17: ='[5]data summary'!C46 -> 75427834 | D17: ='[5]data summary'!D46 -> 7.5056192 | E17: ='[5]data summary'!E46 -> 7.477955e+08 | G17: ='[6]data summary'!M36 -> 0 | H17: ='[6]data summary'!N36 -> 0 | I17: ='[6]data summary'!O36 -> 171.83184 | J17: ='[6]data summary'!P36 -> 19.265308 | K17: ='[6]data summary'!Q36 -> 0 | L17: ='[6]data summary'!R36 -> 0 | M17: ='[6]data summary'!S36 -> 14.326419 | N17: ='[6]data summary'!T36 -> 1.5959155 | ... S17: ='[6]data summary'!Y36 -> 0
... A20: ='[5]data summary'!A49 -> 0 | B20: ='[5]data summary'!B49 -> PBO | C20: ='[5]data summary'!C49 -> 23071749 | D20: ='[5]data summary'!D49 -> 1.1661933 | E20: ='[5]data summary'!E49 -> 1.6186204e+08 | G20: ='[6]data summary'!M39 -> 2030 | H20: ='[6]data summary'!N39 -> 0 | I20: ='[6]data summary'!O39 -> 171.83184 | J20: ='[6]data summary'!P39 -> 19.265308 | K20: ='[6]data summary'!Q39 -> 0 | L20: ='[6]data summary'!R39 -> 0 | M20: ='[6]data summary'!S39 -> 14.326419 | N20: ='[6]data summary'!T39 -> 1.5959155 | ... S20: ='[6]data summary'!Y39 -> 0
A21: ='[5]data summary'!A50 -> 0 | B21: ='[5]data summary'!B50 -> 0 | C21: ='[5]data summary'!C50 -> 1.7183184e+08 | D21: ='[5]data summary'!D50 -> 14.326419 | E21: ='[5]data summary'!E50 -> 1.539055e+09
A25: 2
A26: ='[7]data summary'!A35 -> yearly | B26: ='[7]data summary'!B35 -> 0 | C26: ='[7]data summary'!C35 -> CC | D26: ='[7]data summary'!D35 -> HTC | E26: ='[7]data summary'!E35 -> CED | G26: ='[8]data summary'!M25 -> 0 | H26: ='[8]data summary'!N25 -> 0 | I26: ='[8]data summary'!O25 -> CC | J26: ='[8]data summary'!P25 -> CC | K26: ='[8]data summary'!Q25 -> 0 | L26: ='[8]data summary'!R25 -> 0 | M26: ='[8]data summary'!S25 -> HTC | N26: ='[8]data summary'!T25 -> HTC | ... S26: ='[8]data summary'!Y25 -> 0
A27: ='[7]data summary'!A36 -> 2025 | B27: ='[7]data summary'!B36 -> PAG | C27: ='[7]data summary'!C36 -> 4184961.6 | D27: ='[7]data summary'!D36 -> 0.235044 | E27: ='[7]data summary'!E36 -> 29794746 | G27: ='[8]data summary'!M26 -> 2025 | H27: ='[8]data summary'!N26 -> Gas | I27: ='[8]data summary'!O26 -> 0.064946084 | J27: ='[8]data summary'!P26 -> 0.0062352594 | K27: ='[8]data summary'!Q26 -> 0.0029961666 | L27: ='[8]data summary'!R26 -> 0 | M27: ='[8]data summary'!S26 -> 0.0053074665 | N27: ='[8]data summary'!T26 -> 0.00050940972 | ... S27: ='[8]data summary'!Y26 -> 0.0026018208
A28: ='[7]data summary'!A37 -> 0 | B28: ='[7]data summary'!B37 -> Sur | C28: ='[7]data summary'!C37 -> 178559.98 | D28: ='[7]data summary'!D37 -> 0.018817303 | E28: ='[7]data summary'!E37 -> 1731863.1 | G28: ='[8]data summary'!M27 -> 0 | H28: ='[8]data summary'!N27 -> Solid | I28: ='[8]data summary'!O27 -> 0.076988336 | J28: ='[8]data summary'!P27 -> 0.0073937634 | K28: ='[8]data summary'!Q27 -> 0.0035517134 | L28: ='[8]data summary'!R27 -> 0 | M28: ='[8]data summary'!S27 -> 0.006291489 | N28: ='[8]data summary'!T27 -> 0.00060404922 | ... S28: ='[8]data summary'!Y27 -> 0.0030842435
A29: ='[7]data summary'!A38 -> 0 | B29: ='[7]data summary'!B38 -> TARC | C29: ='[7]data summary'!C38 -> 9453353.9 | D29: ='[7]data summary'!D38 -> 0.97324892 | E29: ='[7]data summary'!E38 -> 90489608 | G29: ='[8]data summary'!M28 -> 0 | H29: ='[8]data summary'!N28 -> Solvent | I29: ='[8]data summary'!O28 -> 7.7591649 | J29: ='[8]data summary'!P28 -> 0.74486089 | K29: ='[8]data summary'!Q28 -> 0.35795462 | L29: ='[8]data summary'!R28 -> 0 | M29: ='[8]data summary'!S28 -> 0.40902614 | N29: ='[8]data summary'!T28 -> 0.039308737 | ... S29: ='[8]data summary'!Y28 -> 0.28547321
A30: ='[7]data summary'!A39 -> 0 | B30: ='[7]data summary'!B39 -> Polymer | C30: ='[7]data summary'!C39 -> 282696.83 | D30: ='[7]data summary'!D39 -> 0.015679873 | E30: ='[7]data summary'!E39 -> 2002267.6 | G30: ='[8]data summary'!M29 -> 0 | H30: ='[8]data summary'!N29 -> Water | I30: ='[8]data summary'!O29 -> 13.775294 | J30: ='[8]data summary'!P29 -> 1.3230638 | K30: ='[8]data summary'!Q29 -> 0.6354975 | L30: ='[8]data summary'!R29 -> 0 | M30: ='[8]data summary'!S29 -> 1.4603787 | N30: ='[8]data summary'!T29 -> 0.14006828 | ... S30: ='[8]data summary'!Y29 -> 0.70884073
A31: ='[7]data summary'!A40 -> 0 | B31: ='[7]data summary'!B40 -> ITC | C31: ='[7]data summary'!C40 -> 5040214.7 | D31: ='[7]data summary'!D40 -> 0.50091453 | E31: ='[7]data summary'!E40 -> 47315732 | G31: ='[8]data summary'!M30 -> 0 | H31: ='[8]data summary'!N30 -> 0 | I31: ='[8]data summary'!O30 -> 21.676393 | J31: ='[8]data summary'!P30 -> 2.0815537 | K31: ='[8]data summary'!Q30 -> 0 | L31: ='[8]data summary'!R30 -> 0 | M31: ='[8]data summary'!S30 -> 1.8810038 | N31: ='[8]data summary'!T30 -> 0.18049047 | ... S31: ='[8]data summary'!Y30 -> 0
A32: ='[7]data summary'!A41 -> 0 | B32: ='[7]data summary'!B41 -> PBO | C32: ='[7]data summary'!C41 -> 2536605.9 | D32: ='[7]data summary'!D41 -> 0.13729921 | E32: ='[7]data summary'!E41 -> 17818194 | G32: ='[8]data summary'!M31 -> 0 | H32: ='[8]data summary'!N31 -> 0 | I32: ='[8]data summary'!O31 -> 0 | J32: ='[8]data summary'!P31 -> 0 | K32: ='[8]data summary'!Q31 -> 0 | L32: ='[8]data summary'!R31 -> 0 | M32: ='[8]data summary'!S31 -> 0 | N32: ='[8]data summary'!T31 -> 0 | ... S32: ='[8]data summary'!Y31 -> 0
A33: ='[7]data summary'!A42 -> 0 | B33: ='[7]data summary'!B42 -> 0 | C33: ='[7]data summary'!C42 -> 21676393 | D33: ='[7]data summary'!D42 -> 1.8810038 | E33: ='[7]data summary'!E42 -> 1.8915241e+08 | G33: ='[8]data summary'!M32 -> 2030 | H33: ='[8]data summary'!N32 -> Gas | I33: ='[8]data summary'!O32 -> 0.45881366 | J33: ='[8]data summary'!P32 -> 0.05142087 | K33: ='[8]data summary'!Q32 -> 0.0029110094 | L33: ='[8]data summary'!R32 -> 0 | M33: ='[8]data summary'!S32 -> 0.035670039 | N33: ='[8]data summary'!T32 -> 0.0039943419 | ... S33: ='[8]data summary'!Y32 -> 0.002537968
A34: ='[7]data summary'!A43 -> 0 | B34: ='[7]data summary'!B43 -> 0 | C34: ='[7]data summary'!C43 -> 0 | D34: ='[7]data summary'!D43 -> 0 | E34: ='[7]data summary'!E43 -> 0 | G34: ='[8]data summary'!M33 -> 0 | H34: ='[8]data summary'!N33 -> Solid | I34: ='[8]data summary'!O33 -> 0.59206575 | J34: ='[8]data summary'!P33 -> 0.06635985 | K34: ='[8]data summary'!Q33 -> 0.0037564464 | L34: ='[8]data summary'!R33 -> 0 | M34: ='[8]data summary'!S33 -> 0.046028072 | N34: ='[8]data summary'!T33 -> 0.0051546288 | ... S34: ='[8]data summary'!Y33 -> 0.0032750514
A35: ='[7]data summary'!A44 -> 2030 | B35: ='[7]data summary'!B44 -> PAG | C35: ='[7]data summary'!C44 -> 30041391 | D35: ='[7]data summary'!D44 -> 1.5670946 | E35: ='[7]data summary'!E44 -> 2.1299652e+08 | G35: ='[8]data summary'!M34 -> 0 | H35: ='[8]data summary'!N34 -> Solvent | I35: ='[8]data summary'!O34 -> 60.6944 | J35: ='[8]data summary'!P34 -> 6.7499898 | K35: ='[8]data summary'!Q34 -> 0.38508436 | L35: ='[8]data summary'!R34 -> 0 | M35: ='[8]data summary'!S34 -> 2.9771027 | N35: ='[8]data summary'!T34 -> 0.3372466 | ... S35: ='[8]data summary'!Y34 -> 0.3091239
A36: ='[7]data summary'!A45 -> 0 | B36: ='[7]data summary'!B45 -> Sur | C36: ='[7]data summary'!C45 -> 1213893.3 | D36: ='[7]data summary'!D45 -> 0.11942581 | E36: ='[7]data summary'!E45 -> 11770940 | G36: ='[8]data summary'!M35 -> 0 | H36: ='[8]data summary'!N35 -> Water | I36: ='[8]data summary'!O35 -> 95.867975 | J36: ='[8]data summary'!P35 -> 10.865669 | K36: ='[8]data summary'!Q35 -> 0.60824818 | L36: ='[8]data summary'!R35 -> 0 | M36: ='[8]data summary'!S35 -> 9.4910862 | N36: ='[8]data summary'!T35 -> 1.0597206 | ... S36: ='[8]data summary'!Y35 -> 0.68506308
A37: ='[7]data summary'!A46 -> 0 | B37: ='[7]data summary'!B46 -> TARC | C37: ='[7]data summary'!C46 -> 66211329 | D37: ='[7]data summary'!D46 -> 6.3542919 | E37: ='[7]data summary'!E46 -> 6.3310341e+08 | G37: ='[8]data summary'!M36 -> 0 | H37: ='[8]data summary'!N36 -> 0 | I37: ='[8]data summary'!O36 -> 157.61325 | J37: ='[8]data summary'!P36 -> 17.733439 | K37: ='[8]data summary'!Q36 -> 0 | L37: ='[8]data summary'!R36 -> 0 | M37: ='[8]data summary'!S36 -> 12.549887 | N37: ='[8]data summary'!T36 -> 1.4061162 | ... S37: ='[8]data summary'!Y36 -> 0
... A40: ='[7]data summary'!A49 -> 0 | B40: ='[7]data summary'!B49 -> PBO | C40: ='[7]data summary'!C49 -> 23004476 | D40: ='[7]data summary'!D49 -> 1.1576667 | E40: ='[7]data summary'!E49 -> 1.6101576e+08 | G40: ='[8]data summary'!M39 -> 2030 | H40: ='[8]data summary'!N39 -> 0 | I40: ='[8]data summary'!O39 -> 157.61325 | J40: ='[8]data summary'!P39 -> 17.733439 | K40: ='[8]data summary'!Q39 -> 0 | L40: ='[8]data summary'!R39 -> 0 | M40: ='[8]data summary'!S39 -> 12.549887 | N40: ='[8]data summary'!T39 -> 1.4061162 | ... S40: ='[8]data summary'!Y39 -> 0
A41: ='[7]data summary'!A50 -> 0 | B41: ='[7]data summary'!B50 -> 0 | C41: ='[7]data summary'!C50 -> 1.5761325e+08 | D41: ='[7]data summary'!D50 -> 12.549887 | E41: ='[7]data summary'!E50 -> 1.3620931e+09
A45: {=INDEX($A$6:$S$41, COLUMN(A1), ROW(A1))} -> yearly | B45: {=INDEX($A$6:$S$41, COLUMN(B1), ROW(B1))} -> 2025 | C45: {=INDEX($A$6:$S$41, COLUMN(C1), ROW(C1))} -> 0 | D45: {=INDEX($A$6:$S$41, COLUMN(D1), ROW(D1))} -> 0 | E45: {=INDEX($A$6:$S$41, COLUMN(E1), ROW(E1))} -> 0 | F45: {=INDEX($A$6:$S$41, COLUMN(F1), ROW(F1))} -> 0 | G45: {=INDEX($A$6:$S$41, COLUMN(G1), ROW(G1))} -> 0 | H45: {=INDEX($A$6:$S$41, COLUMN(H1), ROW(H1))} -> 0 | ... AJ45: {=INDEX($A$6:$S$41, COLUMN(AJ1), ROW(AJ1))} -> 0
A46: {=INDEX($A$6:$S$41, COLUMN(A2), ROW(A2))} -> 0 | B46: {=INDEX($A$6:$S$41, COLUMN(B2), ROW(B2))} -> PAG | C46: {=INDEX($A$6:$S$41, COLUMN(C2), ROW(C2))} -> Sur | D46: {=INDEX($A$6:$S$41, COLUMN(D2), ROW(D2))} -> TARC | E46: {=INDEX($A$6:$S$41, COLUMN(E2), ROW(E2))} -> Polymer | F46: {=INDEX($A$6:$S$41, COLUMN(F2), ROW(F2))} -> ITC | G46: {=INDEX($A$6:$S$41, COLUMN(G2), ROW(G2))} -> PBO | H46: {=INDEX($A$6:$S$41, COLUMN(H2), ROW(H2))} -> 0 | ... AJ46: {=INDEX($A$6:$S$41, COLUMN(AJ2), ROW(AJ2))} -> 0
A47: {=INDEX($A$6:$S$41, COLUMN(A3), ROW(A3))} -> CC | B47: {=INDEX($A$6:$S$41, COLUMN(B3), ROW(B3))} -> 4225983.1 | C47: {=INDEX($A$6:$S$41, COLUMN(C3), ROW(C3))} -> 206300.64 | D47: {=INDEX($A$6:$S$41, COLUMN(D3), ROW(D3))} -> 10854831 | E47: {=INDEX($A$6:$S$41, COLUMN(E3), ROW(E3))} -> 284880.4 | F47: {=INDEX($A$6:$S$41, COLUMN(F3), ROW(F3))} -> 5735174.8 | G47: {=INDEX($A$6:$S$41, COLUMN(G3), ROW(G3))} -> 2548908.9 | H47: {=INDEX($A$6:$S$41, COLUMN(H3), ROW(H3))} -> 23856079 | ... AJ47: {=INDEX($A$6:$S$41, COLUMN(AJ3), ROW(AJ3))} -> 1.5761325e+08
